Workbook
Name Put_W: Monat!$Z$11
Name FZC_1: Monat!$AC$18
Name Gleit_Tag: Monat!$AC$10
Name Brue_H: Monat!$Z$4
Name Urlaub_1: Monat!$AC$11
Name Sekre_1: Monat!$AC$14
Name Unt_II: Monat!$AC$8
Name Muster: Monat!$Z$8
Name NST_1: Monat!$AC$19
Name Koor_taet: Monat!$AC$13
Name Rath_M: Monat!$Z$5
Name Krem_E: Monat!$Z$10
Name Nacht_1: Monat!$AC$5
Name Velt_M: Monat!$Z$3
Name Wuert_A: Monat!$Z$8
Name Frueh_1: Monat!$AC$3
Name Normal_1: Monat!$AC$6
Name Spaet_1: Monat!$AC$4
Name Sonderd_1: Monat!$AC$9
Name Fort_b: Monat!$AC$15
Name Fortenb: Monat!$Z$13
Name Radi_L: Monat!$Z$12
Name Scho_K: Monat!$Z$6
Name EH_Kurs: Monat!$AC$12
Name Velten_M: Monat!$Z$3
Name Velten: Monat!$Z$3
Name Krie_B: Monat!$Z$7
Name Unt_I: Monat!$AC$7

Sheet Dienstplan
B2: Jahr | C2: 2026
M3: Jan | Q3: =C2 -> 2026 | AR3: Feb | AV3: =C2 -> 2026 | BT3: Mrz | BX3: =C2 -> 2026 | CY3: Apr | DC3: =C2 -> 2026 | EE3: Mai | EI3: =C2 -> 2026 | FH3: Jun | FL3: =C2 -> 2026
C4: Weihnachtsferien | AU4: Faschingsferien | CK4: Osterferien | EO4: Pfingstferien
C5: KW 1 | G5: KW 2 | N5: KW 3 | U5: KW 4 | AB5: KW 5 | AI5: KW 6 | AP5: KW 7 | AW5: KW 8 | BD5: KW 9 | BK5: KW 10 | BR5: KW 11 | BY5: KW 12 | CF5: KW 13 | CM5: KW 14 | CT5: KW 15 | DA5: KW 16 | DH5: KW 17 | DO5: KW 18 | DV5: KW 19 | EC5: KW 20 | EJ5: KW 21 | EQ5: KW 22 | EX5: KW 23 | FE5: KW 24 | FL5: KW 25 | FS5: KW 26 | FZ5: KW 27
C6: 1 | D6: 2 | E6: 3 | F6: 4 | G6: 5 | H6: 6 | I6: 7 | J6: 8 | K6: 9 | L6: 10 | M6: 11 | N6: 12 | O6: 13 | P6: 14 | Q6: 15 | R6: 16 | S6: 17 | T6: 18 | U6: 19 | V6: 20 | W6: 21 | X6: 22 | Y6: 23 | Z6: 24 | AA6: 25 | AB6: 26 | AC6: 27 | AD6: 28 | AE6: 29 | AF6: 30 | AG6: 31 | AH6: 1 | AI6: 2 | AJ6: 3 | AK6: 4 | AL6: 5 | AM6: 6 | AN6: 7 | AO6: 8 | AP6: 9 | AQ6: 10 | AR6: 11 | AS6: 12 | AT6: 13 | AU6: 14 | AV6: 15 | AW6: 16 | AX6: 17 | AY6: 18 | AZ6: 19 | BA6: 20 | BB6: 21 | BC6: 22 | BD6: 23 | BE6: 24 | BF6: 25 | BG6: 26 | BH6: 27 | BI6: 28 | BJ6: 1 | BK6: 2 | BL6: 3 | BM6: 4 | BN6: 5 | BO6: 6 | BP6: 7 | BQ6: 8 | BR6: 9 | BS6: 10 | BT6: 11 | BU6: 12 | BV6: 13 | BW6: 14 | BX6: 15 | BY6: 16 | BZ6: 17 | CA6: 18 | CB6: 19 | CC6: 20 | CD6: 21 | CE6: 22 | CF6: 23 | CG6: 24 | CH6: 25 | CI6: 26 | CJ6: 27 | CK6: 28 | CL6: 29 | CM6: 30 | CN6: 31 | CO6: 1 | CP6: 2 | CQ6: 3 | CR6: 4 | CS6: 5 | CT6: 6 | CU6: 7 | CV6: 8 | CW6: 9 | CX6: 10 | CY6: 11 | CZ6: 12 | DA6: 13 | DB6: 14 | DC6: 15 | DD6: 16 | DE6: 17 | DF6: 18 | DG6: 19 | DH6: 20 | DI6: 21 | DJ6: 22 | DK6: 23 | DL6: 24 | DM6: 25 | DN6: 26 | DO6: 27 | DP6: 28 | DQ6: 29 | DR6: 30 | DS6: 1 | DT6: 2 | DU6: 3 | DV6: 4 | DW6: 5 | DX6: 6 | DY6: 7 | DZ6: 8 | EA6: 9 | EB6: 10 | EC6: 11 | ED6: 12 | EE6: 13 | EF6: 14 | EG6: 15 | EH6: 16 | EI6: 17 | EJ6: 18 | EK6: 19 | EL6: 20 | EM6: 21 | EN6: 22 | EO6: 23 | EP6: 24 | EQ6: 25 | ER6: 26 | ES6: 27 | ET6: 28 | EU6: 29 | EV6: 30 | EW6: 31 | EX6: 1 | EY6: 2 | EZ6: 3 | FA6: 4 | FB6: 5 | FC6: 6 | FD6: 7 | FE6: 8 | FF6: 9 | FG6: 10 | FH6: 11 | FI6: 12 | FJ6: 13 | FK6: 14 | FL6: 15 | FM6: 16 | FN6: 17 | FO6: 18 | FP6: 19 | FQ6: 20 | FR6: 21 | FS6: 22 | FT6: 23 | FU6: 24 | FV6: 25 | FW6: 26 | FX6: 27 | FY6: 28 | FZ6: 29 | GA6: 30
C7: Do | D7: Fr | E7: Sa | F7: So | G7: Mo | H7: Di | I7: Mi | J7: Do | K7: Fr | L7: Sa | M7: So | N7: Mo | O7: Di | P7: Mi | Q7: Do | R7: Fr | S7: Sa | T7: So | U7: Mo | V7: Di | W7: Mi | X7: Do | Y7: Fr | Z7: Sa | AA7: So | AB7: Mo | AC7: Di | AD7: Mi | AE7: Do | AF7: Fr | AG7: Sa | AH7: So | AI7: Mo | AJ7: Di | AK7: Mi | AL7: Do | AM7: Fr | AN7: Sa | AO7: So | AP7: Mo | AQ7: Di | AR7: Mi | AS7: Do | AT7: Fr | AU7: Sa | AV7: So | AW7: Mo | AX7: Di | AY7: Mi | AZ7: Do | BA7: Fr | BB7: Sa | BC7: So | BD7: Mo | BE7: Di | BF7: Mi | BG7: Do | BH7: Fr | BI7: Sa | BJ7: So | BK7: Mo | BL7: Di | BM7: Mi | BN7: Do | BO7: Fr | BP7: Sa | BQ7: So | BR7: Mo | BS7: Di | BT7: Mi | BU7: Do | BV7: Fr | BW7: Sa | BX7: So | BY7: Mo | BZ7: Di | CA7: Mi | CB7: Do | CC7: Fr | CD7: Sa | CE7: So | CF7: Mo | CG7: Di | CH7: Mi | CI7: Do | CJ7: Fr | CK7: Sa | CL7: So | CM7: Mo | CN7: Di | CO7: Mi | CP7: Do | CQ7: Fr | CR7: Sa | CS7: So | CT7: Mo | CU7: Di | CV7: Mi | CW7: Do | CX7: Fr | CY7: Sa | CZ7: So | DA7: Mo | DB7: Di | DC7: Mi | DD7: Do | DE7: Fr | DF7: Sa | DG7: So | DH7: Mo | DI7: Di | DJ7: Mi | DK7: Do | DL7: Fr | DM7: Sa | DN7: So | DO7: Mo | DP7: Di | DQ7: Mi | DR7: Do | DS7: Fr | DT7: Sa | DU7: So | DV7: Mo | DW7: Di | DX7: Mi | DY7: Do | DZ7: Fr | EA7: Sa | EB7: So | EC7: Mo | ED7: Di | EE7: Mi | EF7: Do | EG7: Fr | EH7: Sa | EI7: So | EJ7: Mo | EK7: Di | EL7: Mi | EM7: Do | EN7: Fr | EO7: Sa | EP7: So | EQ7: Mo | ER7: Di | ES7: Mi | ET7: Do | EU7: Fr | EV7: Sa | EW7: So | EX7: Mo | EY7: Di | EZ7: Mi | FA7: Do | FB7: Fr | FC7: Sa | FD7: So | FE7: Mo | FF7: Di | FG7: Mi | FH7: Do | FI7: Fr | FJ7: Sa | FK7: So | FL7: Mo | FM7: Di | FN7: Mi | FO7: Do | FP7: Fr | FQ7: Sa | FR7: So | FS7: Mo | FT7: Di | FU7: Mi | FV7: Do | FW7: Fr | FX7: Sa | FY7: So | FZ7: Mo | GA7: Di
B8: Breig | D8: U alt | G8: U alt | I8: NI | J8: NI | K8: GT | N8: SI | O8: SI | P8: SI | Q8: SI | R8: SI | U8: FII | V8: FII | W8: FII | X8: FII | Y8: FII | AB8: KU | AC8: FII | AD8: DI | AE8: KU | AF8: DI | AH8: NI | AI8: NI | AJ8: NI | AK8: NI | AL8: NI | AM8: NST | AP8: SI | AQ8: SI | AR8: SI | AS8: SI | AT8: SI | AW8: FII | AX8: FII | AY8: EH | AZ8: DI | BA8: FI | BD8: FI | BE8: FI | BF8: FI | BG8: FI | BH8: FI | BK8: Fobi | BL8: Fobi | BM8: Fobi | BN8: DI | BO8: DI | BQ8: NI | BR8: NI | BS8: NI | BT8: NI | BU8: NI | BV8: NST | CA8: EH | CB8: Fobi | CC8: Fobi | CF8: FI | CG8: FI | CH8: FI | CI8: FI | CJ8: FI | CU8: NI | CV8: NI | CW8: NI | CX8: NST | DA8: SI | DB8: SI | DC8: SI | DD8: SI | DE8: SI | DH8: FI | DI8: FI | DJ8: FI | DK8: FI | DL8: FI | EI8: NI | EJ8: NI | EK8: NI | EL8: NI | EM8: NI | EN8: NST | ER8: U | ES8: U | ET8: U | EU8: U | EX8: U | EY8: U | EZ8: U | FB8: U | FY8: NI | FZ8: NI | GA8: NI
B9: Siebert | D9: U alt | G9: NST | I9: FII | J9: FII | K9: FII | L9: FI | M9: NI | N9: NI | O9: NI | P9: NI | Q9: NI | R9: NST | U9: SI | V9: SI | W9: SI | X9: SI | Y9: SI | AB9: FI | AC9: FI | AD9: FI | AE9: FI | AF9: FI | AI9: KU | AJ9: FII | AK9: FII | AL9: KU | AM9: FI | AO9: NI | AP9: NI | AQ9: NI | AR9: NI | AS9: NI | AT9: NST | AW9: SI | AX9: SI | AY9: SI | AZ9: SI | BA9: SI | BC9: NI | BD9: NI | BE9: NI | BF9: NI | BG9: NI | BH9: NI | BK9: SI | BL9: SI | BM9: SI | BN9: SI | BO9: SI | CB9: Fobi | CC9: Fobi | CH9: EH | CI9: U | CJ9: U | CM9: U | CN9: U | CO9: U | CP9: U | CU9: U | CV9: U | CW9: U | CX9: U | CZ9: NI | DA9: NI | DB9: NI | DC9: NI | DD9: NI | DE9: NST | DK9: U | DL9: U | EJ9: SI | EK9: SI | EL9: SI | EM9: SI | EN9: SI | EW9: NI | EX9: NI | EY9: NI | EZ9: NI | FB9: NST | FE9: SI | FF9: SI | FG9: SI | FH9: SI | FI9: SI | FZ9: U | GA9: U
B10: Jochim | BD10: (DI) 2h | BF10: (DI) 2h | BH10: (DI) 2h | BK10: (DII) xh | BL10: (DII) xh | BM10: (DII) xh | BN10: (DII) xh | BO10: (DII) xh | BR10: (FI) xh | BS10: (FI) xh | BT10: (FI) xh | BU10: (FI) xh | BV10: (FI) xh | BY10: (DI) xh | BZ10: (DI) xh | CA10: (DI) xh | CB10: (DI) xh | CC10: (DI) xh | CH10: SD
B11: Wunsch | D11: SD | G11: SD | I11: DI | J11: DI | K11: DI | N11: FI | O11: FI | P11: FI | Q11: FI | R11: FI | T11: NI | U11: NI | V11: NI | W11: NI | X11: NI | Y11: NST | AB11: SI | AC11: SI | AD11: SI | AE11: SI | AF11: SI | AI11: FI | AJ11: FI | AK11: EH | AL11: SD | AM11: SD | AP11: KU | AQ11: RTW- Des. | AR11: EH | AS11: KU | AT11: DI | AV11: NI | AW11: NI | AX11: NI | AY11: NI | AZ11: NI | BA11: NST | BD11: FII | BE11: FII | BF11: SD | BG11: Fobi | BH11: Fobi | BK11: KU | BM11: EH | BN11: KU | BO11: NST | BP11: FI | BX11: NI | BY11: NI | BZ11: NI | CA11: NI | CB11: NI | CC11: NST | CF11: U | CG11: U | CH11: SI | CI11: SI | CJ11: SI | DA11: Fobi | DB11: Fobi | DC11: Fobi | DJ11: EH | DL11: GT | DN11: NI | DO11: NI | DP11: NI | DQ11: NI | DR11: NI | DV11: U | DW11: U | DX11: U | DY11: U | DZ11: U | EG11: U | ER11: NI | ES11: NI | ET11: NI | EU11: NST | EX11: SI | EY11: SI | EZ11: SI | FB11: SI | FL11: U | FM11: U | FN11: U | FO11: U | FP11: U | FZ11: U
B12: Göpfrich | D12: U alt | G12: U alt | I12: SI | J12: SI | K12: SI | N12: KU | O12: DI | P12: DI | Q12: KU | R12: DI | U12: U | V12: U | W12: U | X12: U | Y12: U | AA12: NI | AB12: NI | AC12: NI | AD12: NI | AE12: NI | AF12: NI | AI12: SI | AJ12: SI | AK12: SI | AL12: SI | AM12: SI | AP12: GT | AQ12: NST | AR12: DI | AS12: DI | AT12: SD | AU12: FI | AW12: FI | AX12: FI | AY12: FI | AZ12: FI | BA12: GT | BD12: KU | BE12: SD | BF12: KU | BG12: Fobi | BH12: Fobi | BJ12: NI | BK12: NI | BL12: NI | BM12: NI | BN12: NI | BO12: NST | BR12: SI | BS12: SI | BT12: SI | BU12: SI | BV12: SI | CE12: NI | CF12: NI | CG12: NI | CH12: NI | CI12: NI | CJ12: NI | CM12: SI | CN12: SI | CO12: SI | CP12: SI | DC12: EH | DH12: SI | DI12: SI | DJ12: SI | DK12: SI | DL12: SI | DO12: U | DP12: U | DQ12: U | DR12: U | DU12: NI | DV12: NI | DW12: NI | DX12: NI | DY12: NI | DZ12: NST | EC12: SI | ED12: SI | EE12: SI | EG12: SI | FG12: Fobi | FH12: Fobi | FI12: Fobi | FK12: NI | FL12: NI | FM12: NI | FN12: NI | FO12: NI | FP12: NST | FS12: SI | FT12: SI | FU12: SI | FV12: SI | FW12: SI
B13: Zeller | D13: U alt | G13: GT | I13: FI | J13: FI | K13: FI | N13: NST | O13: FII | P13: FII | Q13: FII | R13: FII | S13: FI | U13: FI | V13: FI | W13: FI | X13: FI | Y13: FI | AB13: KU | AC13: DI | AD13: DI | AE13: KU | AF13: DI | AI13: GT | AJ13: NST | AK13: FI | AL13: FI | AM13: FI | AN13: FI | AP13: FI | AQ13: FI | AR13: FI | AS13: FI | AT13: FI | AV13: NI | AW13: NI | AX13: NI | AY13: NI | AZ13: NI | BA13: NST | BD13: SI | BE13: SI | BF13: SI | BG13: SI | BH13: SI | BK13: DI | BL13: DI | BM13: DI | BN13: DI | BO13: DI | BW13: FI | CB13: Fobi | CC13: Fobi | CF13: SI | CG13: SI | CH13: GT | CI13: U | CJ13: U | CL13: NI | CM13: NI | CN13: NI | CO13: NI | CP13: NI | CU13: SI | CV13: SI | CW13: SI | CX13: SI | DH13: U | DI13: U | DJ13: U | DK13: U | DL13: U | DO13: U | DP13: U | DQ13: U | DR13: U | DV13: U | DW13: U | DX13: U | DY13: U | DZ13: U | EB13: NI | EC13: NI | ED13: NI | EE13: NI | EG13: NST | EN13: U | FR13: NI | FS13: NI | FT13: NI | FU13: NI | FV13: NI | FW13: NST | FZ13: SI | GA13: SI
B14: Behrendt | AI14: 1.AT | AJ14: FII | AK14: FII | AL14: FII | AM14: FII | AP14: FII | AQ14: FII | AR14: FII | AS14: FII | AT14: FII | AW14: GT | AX14: FII | AY14: FII | AZ14: FII | BA14: FII | BD14: SII | BE14: SII | BF14: SII | BG14: SII | BH14: SII | BK14: FI | BL14: FI | BM14: FI | BN14: FI | BO14: FI | CB14: Fobi | CC14: Fobi | CE14: NI | CF14: NI | CG14: NI | CH14: NI | CI14: NI | CJ14: NST | CM14: SI | CN14: SI | CO14: SI | CP14: SI | DG14: NI | DH14: NI | DI14: NI | DJ14: NI | DK14: NI | DL14: NST | DO14: SI | DP14: SI | DQ14: SI | DR14: SI | FD14: NI | FE14: NI | FF14: NI | FG14: NI | FH14: NI | FI14: NST | FL14: SI | FM14: SI | FN14: SI | FO14: SI | FP14: SI
B15: Krempl | D15: U alt | G15: U alt | I15: GT | J15: KU | K15: GT | N15: DI | O15: GT | P15: GT | Q15: DI | R15: GT | U15: KU | V15: GT | W15: GT | X15: KU | Y15: GT | AB15: DI | AC15: DI | AD15: GT | AE15: DI | AF15: GT | AI15: FII | AJ15: SD | AK15: EH | AL15: GT | AM15: GT | AP15: DI | AQ15: DI | AR15: GT | AS15: GT | AT15: GT | AW15: KU | AX15: DI | AY15: GT | AZ15: KU | BA15: DI | BD15: GT | BE15: GT | BF15: GT | BG15: Fobi | BH15: Fobi | BK15: DI | BL15: DI | BM15: DI | BN15: GT | BO15: GT | BT15: EH | BY15: GT | BZ15: GT | CA15: NST | CB15: DI | CC15: DI | CI15: GT | CU15: U | CV15: U | CW15: U | CX15: U | DL15: GT | ER15: U | ES15: U | ET15: U | EU15: U | EX15: U | EY15: U | EZ15: U | FB15: U | FG15: Fobi | FH15: Fobi | FI15: Fobi
B16: Putschler | D16: U alt | G16: U alt | I16: KT | J16: KT | K16: KT | N16: KT | O16: KT | P16: KT | Q16: KT | R16: KT | U16: KT | V16: KT | W16: U | X16: KT | Y16: KT | AB16: KT | AC16: KT | AD16: KT | AE16: KT | AF16: KT | AI16: KT | AJ16: KT | AK16: KT | AL16: KT | AM16: KT | AP16: KT | AQ16: KT | AR16: EH | AS16: KT | AT16: KT | AW16: U | AX16: U | AY16: U | AZ16: U | BA16: U | BD16: KT | BE16: KT | BF16: KT | BG16: Fobi | BH16: Fobi | BK16: KT | BL16: KT | BM16: KT | BN16: KT | BO16: KT | DA16: Fobi | DB16: Fobi | DC16: Fobi | DL16: GT | DQ16: U | DR16: U | EC16: U | ED16: U | EE16: U | EG16: U | EJ16: U | EK16: U | EL16: U | EM16: U | EN16: U | FB16: U
B17: Kunz | AI17: DI | AJ17: DI | AK17: DI | AL17: DI | AM17: DI | BD17: DI | BE17: DI | BF17: DI | BG17: DI | BH17: DI | BR17: DI | BS17: DI | BT17: DI | BU17: DI | BV17: DI | CM17: DI | CN17: DI
B18: Schmidt | CF18: U | CG18: U | DV18: U | DW18: U | DX18: U | DY18: U | DZ18: U | EG18: U | FB18: U | FL18: U | FM18: U | FN18: U | FO18: U | FP18: U | FZ18: U
B19: Radimersky | CM19: U | CN19: U | CO19: U | CP19: U | CU19: U | CV19: U | CW19: U | CX19: U | ER19: U | ES19: U | ET19: U | EU19: U | EX19: U | EY19: U | EZ19: U
O20: Jul | S20: =C2 -> 2026 | AR20: Aug | AU20: =C2 -> 2026 | BY20: Sep | CB20: =C2 -> 2026 | DB20: Okt | DE20: =C2 -> 2026 | EH20: Nov | EK20: =C2 -> 2026 | FK20: Dez | FN20: =C2 -> 2026
AF21: Sommerferien | DN21: Herbstferien | FV21: Weihnachtsferien
C22: KW 27 | H22: KW 28 | O22: KW 29 | V22: KW 30 | AC22: KW 31 | AJ22: KW 32 | AQ22: KW 33 | AX22: KW 34 | BE22: KW 35 | BL22: KW 36 | BS22: KW 37 | BZ22: KW 38 | CG22: KW 39 | CN22: KW 40 | CU22: KW 41 | DB22: KW 42 | DI22: KW 43 | DP22: KW 44 | DW22: KW 45 | ED22: KW 46 | EK22: KW 47 | ER22: KW 48 | EY22: KW 49 | FF22: KW 50 | FM22: KW 51 | FT22: KW 52 | GA22: KW 1
C23: 1 | D23: 2 | E23: 3 | F23: 4 | G23: 5 | H23: 6 | I23: 7 | J23: 8 | K23: 9 | L23: 10 | M23: 11 | N23: 12 | O23: 13 | P23: 14 | Q23: 15 | R23: 16 | S23: 17 | T23: 18 | U23: 19 | V23: 20 | W23: 21 | X23: 22 | Y23: 23 | Z23: 24 | AA23: 25 | AB23: 26 | AC23: 27 | AD23: 28 | AE23: 29 | AF23: 30 | AG23: 31 | AH23: 1 | AI23: 2 | AJ23: 3 | AK23: 4 | AL23: 5 | AM23: 6 | AN23: 7 | AO23: 8 | AP23: 9 | AQ23: 10 | AR23: 11 | AS23: 12 | AT23: 13 | AU23: 14 | AV23: 15 | AW23: 16 | AX23: 17 | AY23: 18 | AZ23: 19 | BA23: 20 | BB23: 21 | BC23: 22 | BD23: 23 | BE23: 24 | BF23: 25 | BG23: 26 | BH23: 27 | BI23: 28 | BJ23: 29 | BK23: 30 | BL23: 31 | BM23: 1 | BN23: 2 | BO23: 3 | BP23: 4 | BQ23: 5 | BR23: 6 | BS23: 7 | BT23: 8 | BU23: 9 | BV23: 10 | BW23: 11 | BX23: 12 | BY23: 13 | BZ23: 14 | CA23: 15 | CB23: 16 | CC23: 17 | CD23: 18 | CE23: 19 | CF23: 20 | CG23: 21 | CH23: 22 | CI23: 23 | CJ23: 24 | CK23: 25 | CL23: 26 | CM23: 27 | CN23: 28 | CO23: 29 | CP23: 30 | CQ23: 1 | CR23: 2 | CS23: 3 | CT23: 4 | CU23: 5 | CV23: 6 | CW23: 7 | CX23: 8 | CY23: 9 | CZ23: 10 | DA23: 11 | DB23: 12 | DC23: 13 | DD23: 14 | DE23: 15 | DF23: 16 | DG23: 17 | DH23: 18 | DI23: 19 | DJ23: 20 | DK23: 21 | DL23: 22 | DM23: 23 | DN23: 24 | DO23: 25 | DP23: 26 | DQ23: 27 | DR23: 28 | DS23: 29 | DT23: 30 | DU23: 31 | DV23: 1 | DW23: 2 | DX23: 3 | DY23: 4 | DZ23: 5 | EA23: 6 | EB23: 7 | EC23: 8 | ED23: 9 | EE23: 10 | EF23: 11 | EG23: 12 | EH23: 13 | EI23: 14 | EJ23: 15 | EK23: 16 | EL23: 17 | EM23: 18 | EN23: 19 | EO23: 20 | EP23: 21 | EQ23: 22 | ER23: 23 | ES23: 24 | ET23: 25 | EU23: 26 | EV23: 27 | EW23: 28 | EX23: 29 | EY23: 30 | EZ23: 1 | FA23: 2 | FB23: 3 | FC23: 4 | FD23: 5 | FE23: 6 | FF23: 7 | FG23: 8 | FH23: 9 | FI23: 10 | FJ23: 11 | FK23: 12 | FL23: 13 | FM23: 14 | FN23: 15 | FO23: 16 | FP23: 17 | FQ23: 18 | FR23: 19 | FS23: 20 | FT23: 21 | FU23: 22 | FV23: 23 | FW23: 24 | FX23: 25 | FY23: 26 | FZ23: 27 | GA23: 28 | GB23: 29 | GC23: 30 | GD23: 31
C24: Mi | D24: Do | E24: Fr | F24: Sa | G24: So | H24: Mo | I24: Di | J24: Mi | K24: Do | L24: Fr | M24: Sa | N24: So | O24: Mo | P24: Di | Q24: Mi | R24: Do | S24: Fr | T24: Sa | U24: So | V24: Mo | W24: Di | X24: Mi | Y24: Do | Z24: Fr | AA24: Sa | AB24: So | AC24: Mo | AD24: Di | AE24: Mi | AF24: Do | AG24: Fr | AH24: Sa | AI24: So | AJ24: Mo | AK24: Di | AL24: Mi | AM24: Do | AN24: Fr | AO24: Sa | AP24: So | AQ24: Mo | AR24: Di | AS24: Mi | AT24: Do | AU24: Fr | AV24: Sa | AW24: So | AX24: Mo | AY24: Di | AZ24: Mi | BA24: Do | BB24: Fr | BC24: Sa | BD24: So | BE24: Mo | BF24: Di | BG24: Mi | BH24: Do | BI24: Fr | BJ24: Sa | BK24: So | BL24: Mo | BM24: Di | BN24: Mi | BO24: Do | BP24: Fr | BQ24: Sa | BR24: So | BS24: Mo | BT24: Di | BU24: Mi | BV24: Do | BW24: Fr | BX24: Sa | BY24: So | BZ24: Mo | CA24: Di | CB24: Mi | CC24: Do | CD24: Fr | CE24: Sa | CF24: So | CG24: Mo | CH24: Di | CI24: Mi | CJ24: Do | CK24: Fr | CL24: Sa | CM24: So | CN24: Mo | CO24: Di | CP24: Mi | CQ24: Do | CR24: Fr | CS24: Sa | CT24: So | CU24: Mo | CV24: Di | CW24: Mi | CX24: Do | CY24: Fr | CZ24: Sa | DA24: So | DB24: Mo | DC24: Di | DD24: Mi | DE24: Do | DF24: Fr | DG24: Sa | DH24: So | DI24: Mo | DJ24: Di | DK24: Mi | DL24: Do | DM24: Fr | DN24: Sa | DO24: So | DP24: Mo | DQ24: Di | DR24: Mi | DS24: Do | DT24: Fr | DU24: Sa | DV24: So | DW24: Mo | DX24: Di | DY24: Mi | DZ24: Do | EA24: Fr | EB24: Sa | EC24: So | ED24: Mo | EE24: Di | EF24: Mi | EG24: Do | EH24: Fr | EI24: Sa | EJ24: So | EK24: Mo | EL24: Di | EM24: Mi | EN24: Do | EO24: Fr | EP24: Sa | EQ24: So | ER24: Mo | ES24: Di | ET24: Mi | EU24: Do | EV24: Fr | EW24: Sa | EX24: So | EY24: Mo | EZ24: Di | FA24: Mi | FB24: Do | FC24: Fr | FD24: Sa | FE24: So | FF24: Mo | FG24: Di | FH24: Mi | FI24: Do | FJ24: Fr | FK24: Sa | FL24: So | FM24: Mo | FN24: Di | FO24: Mi | FP24: Do | FQ24: Fr | FR24: Sa | FS24: So | FT24: Mo | FU24: Di | FV24: Mi | FW24: Do | FX24: Fr | FY24: Sa | FZ24: So | GA24: Mo | GB24: Di | GC24: Mi | GD24: Do | GE24: Resturlaub | GG24: Zusatzurlaub wg. 50+ Nachtschicht
B25: Breig | C25: NI | D25: NI | E25: NST | O25: U | P25: U | Q25: U | R25: U | S25: U | AP25: NI | AQ25: NI | AR25: NI | AS25: NI | AT25: NI | AU25: NST | AX25: U | AY25: U | AZ25: U | BA25: U | BB25: U | BE25: U | BF25: U | BG25: U | BH25: U | BI25: U | BL25: U | BM25: U | BN25: U | BO25: U | BP25: U | BS25: U | BT25: U | BU25: U | BV25: U | BW25: U | CM25: NI | CN25: NI | CO25: NI | CP25: NI | CQ25: NI | CR25: NST | EC25: NI | ED25: NI | EE25: NI | EF25: NI | EG25: NI | EH25: NST | FS25: NI | FT25: NI | FU25: NI | FV25: NI
B26: Siebert | C26: U | D26: U | E26: U | H26: U | I26: U | J26: U | K26: U | L26: U | N26: NI | O26: NI | P26: NI | Q26: NI | R26: NI | S26: NST | BD26: NI | BE26: NI | BF26: NI | BG26: NI | BH26: NI | BI26: NST | CF26: NI | CG26: NI | CH26: NI | CI26: NI | CJ26: NI | CK26: NST | CU26: U | CV26: U | CW26: U | CX26: U | CY26: U | DB26: U | DC26: U | DD26: U | DE26: U | DF26: U | DW26: NI | DX26: NI | DY26: NI | DZ26: NI | EA26: NST | FE26: NI | FF26: NI | FG26: NI | FH26: NI | FI26: NI | FJ26: NST | FQ26: U | FT26: U | FU26: U | FV26: U | GA26: U | GB26: U | GC26: U
B27: Jochim
B28: Wunsch | D28: Fobi | G28: NI | H28: NI | I28: NI | J28: NI | K28: NI | L28: NST | V28: U | W28: U | X28: U | Y28: U | Z28: U | AC28: U | AD28: U | AN28: U | AQ28: U | BK28: NI | BL28: NI | BM28: NI | BN28: NI | BO28: NI | BP28: NST | CG28: U | CH28: U | CI28: U | CJ28: U | CK28: U | CN28: U | CO28: U | CP28: U | CQ28: U | CR28: U | CT28: NI | CU28: NI | CV28: NI | CW28: NI | CX28: NI | CY28: NST | DL28: U | DM28: U | ED28: U | EJ28: NI | EK28: NI | EL28: NI | EM28: NI | EN28: NI | EO28: NST | EY28: U | EZ28: U
B29: Göpfrich | V29: U | W29: U | X29: U | Y29: U | Z29: U | AB29: NI | AC29: NI | AD29: NI | AE29: NI | AF29: NI | AG29: NST | BR29: NI | BS29: NI | BT29: NI | BU29: NI | BV29: NI | BW29: NST | CG29: U | CH29: U | CI29: U | CJ29: U | CK29: U | DH29: NI | DI29: NI | DJ29: NI | DK29: NI | DL29: NI | DM29: NST | EK29: U | EL29: U | EM29: U | EN29: U | EO29: U | EX29: NI | EY29: NI | EZ29: NI | FA29: NI | FB29: NI | FC29: NST | FT29: U | FU29: U | FV29: U | GA29: U | GB29: U | GC29: U
B30: Zeller | O30: U | P30: U | Q30: U | R30: U | S30: U | AI30: NI | AJ30: NI | AK30: NI | AL30: NI | AM30: NI | AN30: NST | BS30: U | BT30: U | BU30: U | BV30: U | BW30: U | BZ30: U | CA30: U | CB30: U | CC30: U | CD30: U | CO30: Fobi | CP30: Fobi | CQ30: Fobi | DO30: NI | DP30: NI | DQ30: NI | DR30: NI | DS30: NI | DT30: NST | FL30: NI | FM30: NI | FN30: NI | FO30: NI | FP30: NI | FQ30: NST
B31: Behrendt | U31: NI | V31: NI | W31: NI | X31: NI | Y31: NI | Z31: NST | AC31: U | AD31: U | AE31: U | AF31: U | AG31: U | AJ31: U | AK31: U | AL31: U | AM31: U | AN31: U | AW31: NI | AX31: NI | AY31: NI | AZ31: NI | BA31: NI | BB31: NST | BY31: NI | BZ31: NI | CA31: NI | CB31: NI | CC31: NI | CD31: NST | CO31: Fobi | CP31: Fobi | CQ31: Fobi | DA31: NI | DB31: NI | DC31: NI | DD31: NI | DE31: NI | DF31: NST | EQ31: NI | ER31: NI | ES31: NI | ET31: NI | EU31: NI | EV31: NST
B32: Krempl | AJ32: U | AK32: U | AL32: U | AM32: U | AN32: U | AQ32: U | AR32: U | AS32: U | AT32: U | AU32: U | AX32: U | AY32: U | AZ32: U | BA32: U | BB32: U | FT32: U | FU32: U | FV32: U | GA32: U | GB32: U | GC32: U
B33: Putschler | J33: KT | AQ33: U | AR33: U | AS33: U | AT33: U | AU33: U | CU33: U | CV33: U | CW33: U | CX33: U | CY33: U | FT33: U | FU33: U | FV33: U | GA33: U | GB33: U | GC33: U
B34: Kunz
B35: Schmidt | V35: U | W35: U | X35: U | Y35: U | Z35: U | AC35: U | AD35: U | AN35: U | AQ35: U | CG35: U | CH35: U | CI35: U | CJ35: U | CK35: U | CN35: U | CO35: U | CP35: U | CQ35: U | CR35: U | DL35: U | DM35: U | ED35: U | EY35: U | EZ35: U
B36: Radimersky | AG36: U | AX36: U | AY36: U | AZ36: U | BA36: U | BB36: U | BE36: U | BF36: U | BG36: U | BH36: U | BI36: U | BL36: U | BM36: U | BN36: U | BO36: U | BP36: U | BS36: U | BT36: U | BU36: U | BV36: U | BW36: U | DP36: U | DQ36: U | DR36: U | DS36: U | DT36: U
O37: Jan | S37: =C2+1 -> 2027 | AT37: Feb | AX37: =C2+1 -> 2027
C38: Weihnachtsferien
C39: KW 1 | G39: KW 2 | N39: KW 3 | U39: KW 4 | AB39: KW 5 | AI39: KW 6 | AP39: KW 7 | AW39: KW 8 | BD39: KW 9
C40: 1 | D40: 2 | E40: 3 | F40: 4 | G40: 5 | H40: 6 | I40: 7 | J40: 8 | K40: 9 | L40: 10 | M40: 11 | N40: 12 | O40: 13 | P40: 14 | Q40: 15 | R40: 16 | S40: 17 | T40: 18 | U40: 19 | V40: 20 | W40: 21 | X40: 22 | Y40: 23 | Z40: 24 | AA40: 25 | AB40: 26 | AC40: 27 | AD40: 28 | AE40: 29 | AF40: 30 | AG40: 31 | AH40: 1 | AI40: 2 | AJ40: 3 | AK40: 4 | AL40: 5 | AM40: 6 | AN40: 7 | AO40: 8 | AP40: 9 | AQ40: 10 | AR40: 11 | AS40: 12 | AT40: 13 | AU40: 14 | AV40: 15 | AW40: 16 | AX40: 17 | AY40: 18 | AZ40: 19 | BA40: 20 | BB40: 21 | BC40: 22 | BD40: 23 | BE40: 24 | BF40: 25 | BG40: 26 | BH40: 27 | BI40: 28 | CW40: NI | CX40: FZC 83 | CZ40: KT
C41: Fr | D41: Sa | E41: So | F41: Mo | G41: Di | H41: Mi | I41: Do | J41: Fr | K41: Sa | L41: So | M41: Mo | N41: Di | O41: Mi | P41: Do | Q41: Fr | R41: Sa | S41: So | T41: Mo | U41: Di | V41: Mi | W41: Do | X41: Fr | Y41: Sa | Z41: So | AA41: Mo | AB41: Di | AC41: Mi | AD41: Do | AE41: Fr | AF41: Sa | AG41: So | AH41: Mo | AI41: Di | AJ41: Mi | AK41: Do | AL41: Fr | AM41: Sa | AN41: So | AO41: Mo | AP41: Di | AQ41: Mi | AR41: Do | AS41: Fr | AT41: Sa | AU41: So | AV41: Mo | AW41: Di | AX41: Mi | AY41: Do | AZ41: Fr | BA41: Sa | BB41: So | BC41: Mo | BD41: Di | BE41: Mi | BF41: Do | BG41: Fr | BH41: Sa | BI41: So | CX41: QM
...

Sheet Jahr
B2: Jahr | C2: =Dienstplan!C2 -> 2026
C3: =Monat!AB3 -> FI | D3: =Monat!AB4 -> FII | E3: =Monat!AB5 -> SI | F3: =Monat!AB6 -> NI | G3: =Monat!AB7 -> DI | H3: =Monat!AB8 -> DII | I3: =Monat!AB9 -> SD | J3: =Monat!AB10 -> GT | K3: =Monat!AB11 -> U | L3: =Monat!AB12 -> EH | M3: =Monat!AB13 -> KT | N3: =Monat!AB14 -> Sek | O3: =Monat!AB15 -> Fobi | P3: =Monat!AB16 -> A | Q3: =Monat!AB17 -> Kur | R3: =Monat!AB18 -> FZC | S3: =Monat!AB19 -> NST
B4: =Dienstplan!B8 -> Breig | C4: =SUM(Monat!C4,Monat!C20,Monat!C36,Monat!C52,Monat!C68,Monat!C84,Monat!C100+Monat!C116,Monat!C132,Monat!C148,Monat!C164,Monat!C180) -> 16 | D4: =SUM(Monat!D4,Monat!D20,Monat!D36,Monat!D52,Monat!D68,Monat!D84,Monat!D100+Monat!D116,Monat!D132,Monat!D148,Monat!D164,Monat!D180) -> 8 | E4: =SUM(Monat!E4,Monat!E20,Monat!E36,Monat!E52,Monat!E68,Monat!E84,Monat!E100,Monat!E116,Monat!E132,Monat!E148,Monat!E164,Monat!E180) -> 13 | F4: =SUM(Monat!F4,Monat!F20,Monat!F36,Monat!F52,Monat!F68,Monat!F84,Monat!F100+Monat!F116,Monat!F132,Monat!F148,Monat!F164,Monat!F180) -> 43 | G4: =SUM(Monat!G4,Monat!G20,Monat!G36,Monat!G52,Monat!G68,Monat!G84,Monat!G100+Monat!G116,Monat!G132,Monat!G148,Monat!G164,Monat!G180) -> 5 | H4: =SUM(Monat!H4,Monat!H20,Monat!H36,Monat!H52,Monat!H68,Monat!H84,Monat!H100+Monat!H116,Monat!H132,Monat!H148,Monat!H164,Monat!H180) -> 0 | I4: =SUM(Monat!I4,Monat!I20,Monat!I36,Monat!I52,Monat!I68,Monat!I84,Monat!I100+Monat!I116,Monat!I132,Monat!I148,Monat!I164,Monat!I180) -> 0 | J4: =SUM(Monat!J4,Monat!J20,Monat!J36,Monat!J52,Monat!J68,Monat!J84,Monat!J100+Monat!J116,Monat!J132,Monat!J148,Monat!J164,Monat!J180) -> 1 | K4: =SUM(Monat!K4,Monat!K20,Monat!K36,Monat!K52,Monat!K68,Monat!K84,Monat!K100+Monat!K116,Monat!K132,Monat!K148,Monat!K164,Monat!K180) -> 37 | L4: =SUM(Monat!L4,Monat!L20,Monat!L36,Monat!L52,Monat!L68,Monat!L84,Monat!L100+Monat!L116,Monat!L132,Monat!L148,Monat!L164,Monat!L180) -> 2 | M4: =SUM(Monat!M4,Monat!M20,Monat!M36,Monat!M52,Monat!M68,Monat!M84,Monat!M100+Monat!M116,Monat!M132,Monat!M148,Monat!M164,Monat!M180) -> 0 | ... S4: =SUM(Monat!S4,Monat!S20,Monat!S36,Monat!S52,Monat!S68,Monat!S84,Monat!S100+Monat!S116,Monat!S132,Monat!S148,Monat!S164,Monat!S180) -> 8
B5: =Dienstplan!B9 -> Siebert | C5: =SUM(Monat!C5,Monat!C21,Monat!C37,Monat!C53,Monat!C69,Monat!C85,Monat!C101+Monat!C117,Monat!C133,Monat!C149,Monat!C165,Monat!C181) -> 7 | D5: =SUM(Monat!D5,Monat!D21,Monat!D37,Monat!D53,Monat!D69,Monat!D85,Monat!D101+Monat!D117,Monat!D133,Monat!D149,Monat!D165,Monat!D181) -> 5 | E5: =SUM(Monat!E5,Monat!E21,Monat!E37,Monat!E53,Monat!E69,Monat!E85,Monat!E101+Monat!E117,Monat!E133,Monat!E149,Monat!E165,Monat!E181) -> 25 | F5: =SUM(Monat!F5,Monat!F21,Monat!F37,Monat!F53,Monat!F69,Monat!F85,Monat!F101+Monat!F117,Monat!F133,Monat!F149,Monat!F165,Monat!F181) -> 49 | G5: =SUM(Monat!G5,Monat!G21,Monat!G37,Monat!G53,Monat!G69,Monat!G85,Monat!G101+Monat!G117,Monat!G133,Monat!G149,Monat!G165,Monat!G181) -> 0 | H5: =SUM(Monat!H5,Monat!H21,Monat!H37,Monat!H53,Monat!H69,Monat!H85,Monat!H101+Monat!H117,Monat!H133,Monat!H149,Monat!H165,Monat!H181) -> 0 | I5: =SUM(Monat!I5,Monat!I21,Monat!I37,Monat!I53,Monat!I69,Monat!I85,Monat!I101+Monat!I117,Monat!I133,Monat!I149,Monat!I165,Monat!I181) -> 0 | J5: =SUM(Monat!J5,Monat!J21,Monat!J37,Monat!J53,Monat!J69,Monat!J85,Monat!J101+Monat!J117,Monat!J133,Monat!J149,Monat!J165,Monat!J181) -> 0 | ... S5: =SUM(Monat!S5,Monat!S21,Monat!S37,Monat!S53,Monat!S69,Monat!S85,Monat!S101+Monat!S117,Monat!S133,Monat!S149,Monat!S165,Monat!S181) -> 10
B6: =Dienstplan!B10 -> Jochim | C6: =SUM(Monat!C6,Monat!C22,Monat!C38,Monat!C54,Monat!C70,Monat!C86,Monat!C102+Monat!C118,Monat!C134,Monat!C150,Monat!C166,Monat!C182) -> 5 | D6: =SUM(Monat!D6,Monat!D22,Monat!D38,Monat!D54,Monat!D70,Monat!D86,Monat!D102+Monat!D118,Monat!D134,Monat!D150,Monat!D166,Monat!D182) -> 0 | E6: =SUM(Monat!E6,Monat!E22,Monat!E38,Monat!E54,Monat!E70,Monat!E86,Monat!E102+Monat!E118,Monat!E134,Monat!E150,Monat!E166,Monat!E182) -> 0 | F6: =SUM(Monat!F6,Monat!F22,Monat!F38,Monat!F54,Monat!F70,Monat!F86,Monat!F102+Monat!F118,Monat!F134,Monat!F150,Monat!F166,Monat!F182) -> 0 | G6: =SUM(Monat!G6,Monat!G22,Monat!G38,Monat!G54,Monat!G70,Monat!G86,Monat!G102+Monat!G118,Monat!G134,Monat!G150,Monat!G166,Monat!G182) -> 8 | H6: =SUM(Monat!H6,Monat!H22,Monat!H38,Monat!H54,Monat!H70,Monat!H86,Monat!H102+Monat!H118,Monat!H134,Monat!H150,Monat!H166,Monat!H182) -> 5 | I6: =SUM(Monat!I6,Monat!I22,Monat!I38,Monat!I54,Monat!I70,Monat!I86,Monat!I102+Monat!I118,Monat!I134,Monat!I150,Monat!I166,Monat!I182) -> 1 | J6: =SUM(Monat!J6,Monat!J22,Monat!J38,Monat!J54,Monat!J70,Monat!J86,Monat!J102+Monat!J118,Monat!J134,Monat!J150,Monat!J166,Monat!J182) -> 0 | ... S6: =SUM(Monat!S6,Monat!S22,Monat!S38,Monat!S54,Monat!S70,Monat!S86,Monat!S102+Monat!S118,Monat!S134,Monat!S150,Monat!S166,Monat!S182) -> 0
B7: =Dienstplan!B11 -> Wunsch | C7: =SUM(Monat!C7,Monat!C23,Monat!C39,Monat!C55,Monat!C71,Monat!C87,Monat!C103+Monat!C119,Monat!C135,Monat!C151,Monat!C167,Monat!C183) -> 8 | D7: =SUM(Monat!D7,Monat!D23,Monat!D39,Monat!D55,Monat!D71,Monat!D87,Monat!D103+Monat!D119,Monat!D135,Monat!D151,Monat!D167,Monat!D183) -> 2 | E7: =SUM(Monat!E7,Monat!E23,Monat!E39,Monat!E55,Monat!E71,Monat!E87,Monat!E103+Monat!E119,Monat!E135,Monat!E151,Monat!E167,Monat!E183) -> 12 | F7: =SUM(Monat!F7,Monat!F23,Monat!F39,Monat!F55,Monat!F71,Monat!F87,Monat!F103+Monat!F119,Monat!F135,Monat!F151,Monat!F167,Monat!F183) -> 43 | G7: =SUM(Monat!G7,Monat!G23,Monat!G39,Monat!G55,Monat!G71,Monat!G87,Monat!G103+Monat!G119,Monat!G135,Monat!G151,Monat!G167,Monat!G183) -> 4 | H7: =SUM(Monat!H7,Monat!H23,Monat!H39,Monat!H55,Monat!H71,Monat!H87,Monat!H103+Monat!H119,Monat!H135,Monat!H151,Monat!H167,Monat!H183) -> 0 | I7: =SUM(Monat!I7,Monat!I23,Monat!I39,Monat!I55,Monat!I71,Monat!I87,Monat!I103+Monat!I119,Monat!I135,Monat!I151,Monat!I167,Monat!I183) -> 5 | J7: =SUM(Monat!J7,Monat!J23,Monat!J39,Monat!J55,Monat!J71,Monat!J87,Monat!J103+Monat!J119,Monat!J135,Monat!J151,Monat!J167,Monat!J183) -> 1 | ... S7: =SUM(Monat!S7,Monat!S23,Monat!S39,Monat!S55,Monat!S71,Monat!S87,Monat!S103+Monat!S119,Monat!S135,Monat!S151,Monat!S167,Monat!S183) -> 9
B8: =Dienstplan!B12 -> Göpfrich | C8: =SUM(Monat!C8,Monat!C24,Monat!C40,Monat!C56,Monat!C72,Monat!C88,Monat!C104+Monat!C120,Monat!C136,Monat!C152,Monat!C168,Monat!C184) -> 5 | D8: =SUM(Monat!D8,Monat!D24,Monat!D40,Monat!D56,Monat!D72,Monat!D88,Monat!D104+Monat!D120,Monat!D136,Monat!D152,Monat!D168,Monat!D184) -> 0 | E8: =SUM(Monat!E8,Monat!E24,Monat!E40,Monat!E56,Monat!E72,Monat!E88,Monat!E104+Monat!E120,Monat!E136,Monat!E152,Monat!E168,Monat!E184) -> 31 | F8: =SUM(Monat!F8,Monat!F24,Monat!F40,Monat!F56,Monat!F72,Monat!F88,Monat!F104+Monat!F120,Monat!F136,Monat!F152,Monat!F168,Monat!F184) -> 47 | G8: =SUM(Monat!G8,Monat!G24,Monat!G40,Monat!G56,Monat!G72,Monat!G88,Monat!G104+Monat!G120,Monat!G136,Monat!G152,Monat!G168,Monat!G184) -> 5 | H8: =SUM(Monat!H8,Monat!H24,Monat!H40,Monat!H56,Monat!H72,Monat!H88,Monat!H104+Monat!H120,Monat!H136,Monat!H152,Monat!H168,Monat!H184) -> 0 | I8: =SUM(Monat!I8,Monat!I24,Monat!I40,Monat!I56,Monat!I72,Monat!I88,Monat!I104+Monat!I120,Monat!I136,Monat!I152,Monat!I168,Monat!I184) -> 2 | J8: =SUM(Monat!J8,Monat!J24,Monat!J40,Monat!J56,Monat!J72,Monat!J88,Monat!J104+Monat!J120,Monat!J136,Monat!J152,Monat!J168,Monat!J184) -> 2 | ... S8: =SUM(Monat!S8,Monat!S24,Monat!S40,Monat!S56,Monat!S72,Monat!S88,Monat!S104+Monat!S120,Monat!S136,Monat!S152,Monat!S168,Monat!S184) -> 8
B9: =Dienstplan!B13 -> Zeller | C9: =SUM(Monat!C9,Monat!C25,Monat!C41,Monat!C57,Monat!C73,Monat!C89,Monat!C105+Monat!C121,Monat!C137,Monat!C153,Monat!C169,Monat!C185) -> 19 | D9: =SUM(Monat!D9,Monat!D25,Monat!D41,Monat!D57,Monat!D73,Monat!D89,Monat!D105+Monat!D121,Monat!D137,Monat!D153,Monat!D169,Monat!D185) -> 4 | E9: =SUM(Monat!E9,Monat!E25,Monat!E41,Monat!E57,Monat!E73,Monat!E89,Monat!E105+Monat!E121,Monat!E137,Monat!E153,Monat!E169,Monat!E185) -> 13 | F9: =SUM(Monat!F9,Monat!F25,Monat!F41,Monat!F57,Monat!F73,Monat!F89,Monat!F105+Monat!F121,Monat!F137,Monat!F153,Monat!F169,Monat!F185) -> 34 | G9: =SUM(Monat!G9,Monat!G25,Monat!G41,Monat!G57,Monat!G73,Monat!G89,Monat!G105+Monat!G121,Monat!G137,Monat!G153,Monat!G169,Monat!G185) -> 8 | H9: =SUM(Monat!H9,Monat!H25,Monat!H41,Monat!H57,Monat!H73,Monat!H89,Monat!H105+Monat!H121,Monat!H137,Monat!H153,Monat!H169,Monat!H185) -> 0 | I9: =SUM(Monat!I9,Monat!I25,Monat!I41,Monat!I57,Monat!I73,Monat!I89,Monat!I105+Monat!I121,Monat!I137,Monat!I153,Monat!I169,Monat!I185) -> 0 | J9: =SUM(Monat!J9,Monat!J25,Monat!J41,Monat!J57,Monat!J73,Monat!J89,Monat!J105+Monat!J121,Monat!J137,Monat!J153,Monat!J169,Monat!J185) -> 3 | ... S9: =SUM(Monat!S9,Monat!S25,Monat!S41,Monat!S57,Monat!S73,Monat!S89,Monat!S105+Monat!S121,Monat!S137,Monat!S153,Monat!S169,Monat!S185) -> 8
B10: =Dienstplan!B14 -> Behrendt | C10: =SUM(Monat!C10,Monat!C26,Monat!C42,Monat!C58,Monat!C74,Monat!C90,Monat!C106+Monat!C122,Monat!C138,Monat!C154,Monat!C170,Monat!C186) -> 5 | D10: =SUM(Monat!D10,Monat!D26,Monat!D42,Monat!D58,Monat!D74,Monat!D90,Monat!D106+Monat!D122,Monat!D138,Monat!D154,Monat!D170,Monat!D186) -> 13 | E10: =SUM(Monat!E10,Monat!E26,Monat!E42,Monat!E58,Monat!E74,Monat!E90,Monat!E106+Monat!E122,Monat!E138,Monat!E154,Monat!E170,Monat!E186) -> 18 | F10: =SUM(Monat!F10,Monat!F26,Monat!F42,Monat!F58,Monat!F74,Monat!F90,Monat!F106+Monat!F122,Monat!F138,Monat!F154,Monat!F170,Monat!F186) -> 40 | G10: =SUM(Monat!G10,Monat!G26,Monat!G42,Monat!G58,Monat!G74,Monat!G90,Monat!G106+Monat!G122,Monat!G138,Monat!G154,Monat!G170,Monat!G186) -> 0 | H10: =SUM(Monat!H10,Monat!H26,Monat!H42,Monat!H58,Monat!H74,Monat!H90,Monat!H106+Monat!H122,Monat!H138,Monat!H154,Monat!H170,Monat!H186) -> 0 | I10: =SUM(Monat!I10,Monat!I26,Monat!I42,Monat!I58,Monat!I74,Monat!I90,Monat!I106+Monat!I122,Monat!I138,Monat!I154,Monat!I170,Monat!I186) -> 0 | J10: =SUM(Monat!J10,Monat!J26,Monat!J42,Monat!J58,Monat!J74,Monat!J90,Monat!J106+Monat!J122,Monat!J138,Monat!J154,Monat!J170,Monat!J186) -> 1 | ... S10: =SUM(Monat!S10,Monat!S26,Monat!S42,Monat!S58,Monat!S74,Monat!S90,Monat!S106+Monat!S122,Monat!S138,Monat!S154,Monat!S170,Monat!S186) -> 8
B11: =Dienstplan!B15 -> Krempl | C11: =SUM(Monat!C11,Monat!C27,Monat!C43,Monat!C59,Monat!C75,Monat!C91,Monat!C107+Monat!C123,Monat!C139,Monat!C155,Monat!C171,Monat!C187) -> 0 | D11: =SUM(Monat!D11,Monat!D27,Monat!D43,Monat!D59,Monat!D75,Monat!D91,Monat!D107+Monat!D123,Monat!D139,Monat!D155,Monat!D171,Monat!D187) -> 1 | E11: =SUM(Monat!E11,Monat!E27,Monat!E43,Monat!E59,Monat!E75,Monat!E91,Monat!E107+Monat!E123,Monat!E139,Monat!E155,Monat!E171,Monat!E187) -> 0 | F11: =SUM(Monat!F11,Monat!F27,Monat!F43,Monat!F59,Monat!F75,Monat!F91,Monat!F107+Monat!F123,Monat!F139,Monat!F155,Monat!F171,Monat!F187) -> 0 | G11: =SUM(Monat!G11,Monat!G27,Monat!G43,Monat!G59,Monat!G75,Monat!G91,Monat!G107+Monat!G123,Monat!G139,Monat!G155,Monat!G171,Monat!G187) -> 14 | H11: =SUM(Monat!H11,Monat!H27,Monat!H43,Monat!H59,Monat!H75,Monat!H91,Monat!H107+Monat!H123,Monat!H139,Monat!H155,Monat!H171,Monat!H187) -> 0 | I11: =SUM(Monat!I11,Monat!I27,Monat!I43,Monat!I59,Monat!I75,Monat!I91,Monat!I107+Monat!I123,Monat!I139,Monat!I155,Monat!I171,Monat!I187) -> 1 | J11: =SUM(Monat!J11,Monat!J27,Monat!J43,Monat!J59,Monat!J75,Monat!J91,Monat!J107+Monat!J123,Monat!J139,Monat!J155,Monat!J171,Monat!J187) -> 25 | ... S11: =SUM(Monat!S11,Monat!S27,Monat!S43,Monat!S59,Monat!S75,Monat!S91,Monat!S107+Monat!S123,Monat!S139,Monat!S155,Monat!S171,Monat!S187) -> 1
B12: =Dienstplan!B16 -> Putschler | C12: =SUM(Monat!C12,Monat!C28,Monat!C44,Monat!C60,Monat!C76,Monat!C92,Monat!C108+Monat!C124,Monat!C140,Monat!C156,Monat!C172,Monat!C188) -> 0 | D12: =SUM(Monat!D12,Monat!D28,Monat!D44,Monat!D60,Monat!D76,Monat!D92,Monat!D108+Monat!D124,Monat!D140,Monat!D156,Monat!D172,Monat!D188) -> 0 | E12: =SUM(Monat!E12,Monat!E28,Monat!E44,Monat!E60,Monat!E76,Monat!E92,Monat!E108+Monat!E124,Monat!E140,Monat!E156,Monat!E172,Monat!E188) -> 0 | F12: =SUM(Monat!F12,Monat!F28,Monat!F44,Monat!F60,Monat!F76,Monat!F92,Monat!F108+Monat!F124,Monat!F140,Monat!F156,Monat!F172,Monat!F188) -> 0 | G12: =SUM(Monat!G12,Monat!G28,Monat!G44,Monat!G60,Monat!G76,Monat!G92,Monat!G108+Monat!G124,Monat!G140,Monat!G156,Monat!G172,Monat!G188) -> 0 | H12: =SUM(Monat!H12,Monat!H28,Monat!H44,Monat!H60,Monat!H76,Monat!H92,Monat!H108+Monat!H124,Monat!H140,Monat!H156,Monat!H172,Monat!H188) -> 0 | I12: =SUM(Monat!I12,Monat!I28,Monat!I44,Monat!I60,Monat!I76,Monat!I92,Monat!I108+Monat!I124,Monat!I140,Monat!I156,Monat!I172,Monat!I188) -> 0 | J12: =SUM(Monat!J12,Monat!J28,Monat!J44,Monat!J60,Monat!J76,Monat!J92,Monat!J108+Monat!J124,Monat!J140,Monat!J156,Monat!J172,Monat!J188) -> 1 | ... S12: =SUM(Monat!S12,Monat!S28,Monat!S44,Monat!S60,Monat!S76,Monat!S92,Monat!S108+Monat!S124,Monat!S140,Monat!S156,Monat!S172,Monat!S188) -> 0
B13: =Dienstplan!B18 -> Schmidt | C13: =SUM(Monat!C13,Monat!C29,Monat!C45,Monat!C61,Monat!C77,Monat!C93,Monat!C109+Monat!C125,Monat!C141,Monat!C157,Monat!C173,Monat!C189) -> 0 | D13: =SUM(Monat!D13,Monat!D29,Monat!D45,Monat!D61,Monat!D77,Monat!D93,Monat!D109+Monat!D125,Monat!D141,Monat!D157,Monat!D173,Monat!D189) -> 0 | E13: =SUM(Monat!E13,Monat!E29,Monat!E45,Monat!E61,Monat!E77,Monat!E93,Monat!E109+Monat!E125,Monat!E141,Monat!E157,Monat!E173,Monat!E189) -> 0 | F13: =SUM(Monat!F13,Monat!F29,Monat!F45,Monat!F61,Monat!F77,Monat!F93,Monat!F109+Monat!F125,Monat!F141,Monat!F157,Monat!F173,Monat!F189) -> 0 | G13: =SUM(Monat!G13,Monat!G29,Monat!G45,Monat!G61,Monat!G77,Monat!G93,Monat!G109+Monat!G125,Monat!G141,Monat!G157,Monat!G173,Monat!G189) -> 0 | H13: =SUM(Monat!H13,Monat!H29,Monat!H45,Monat!H61,Monat!H77,Monat!H93,Monat!H109+Monat!H125,Monat!H141,Monat!H157,Monat!H173,Monat!H189) -> 0 | I13: =SUM(Monat!I13,Monat!I29,Monat!I45,Monat!I61,Monat!I77,Monat!I93,Monat!I109+Monat!I125,Monat!I141,Monat!I157,Monat!I173,Monat!I189) -> 0 | J13: =SUM(Monat!J13,Monat!J29,Monat!J45,Monat!J61,Monat!J77,Monat!J93,Monat!J109+Monat!J125,Monat!J141,Monat!J157,Monat!J173,Monat!J189) -> 0 | ... S13: =SUM(Monat!S13,Monat!S29,Monat!S45,Monat!S61,Monat!S77,Monat!S93,Monat!S109+Monat!S125,Monat!S141,Monat!S157,Monat!S173,Monat!S189) -> 0
B14: =Dienstplan!B19 -> Radimersky | C14: =SUM(Monat!C14,Monat!C30,Monat!C46,Monat!C62,Monat!C78,Monat!C94,Monat!C110+Monat!C126,Monat!C142,Monat!C158,Monat!C174,Monat!C190) -> 0 | D14: =SUM(Monat!D14,Monat!D30,Monat!D46,Monat!D62,Monat!D78,Monat!D94,Monat!D110+Monat!D126,Monat!D142,Monat!D158,Monat!D174,Monat!D190) -> 0 | E14: =SUM(Monat!E14,Monat!E30,Monat!E46,Monat!E62,Monat!E78,Monat!E94,Monat!E110+Monat!E126,Monat!E142,Monat!E158,Monat!E174,Monat!E190) -> 0 | F14: =SUM(Monat!F14,Monat!F30,Monat!F46,Monat!F62,Monat!F78,Monat!F94,Monat!F110+Monat!F126,Monat!F142,Monat!F158,Monat!F174,Monat!F190) -> 0 | G14: =SUM(Monat!G14,Monat!G30,Monat!G46,Monat!G62,Monat!G78,Monat!G94,Monat!G110+Monat!G126,Monat!G142,Monat!G158,Monat!G174,Monat!G190) -> 0 | H14: =SUM(Monat!H14,Monat!H30,Monat!H46,Monat!H62,Monat!H78,Monat!H94,Monat!H110+Monat!H126,Monat!H142,Monat!H158,Monat!H174,Monat!H190) -> 0 | I14: =SUM(Monat!I14,Monat!I30,Monat!I46,Monat!I62,Monat!I78,Monat!I94,Monat!I110+Monat!I126,Monat!I142,Monat!I158,Monat!I174,Monat!I190) -> 0 | J14: =SUM(Monat!J14,Monat!J30,Monat!J46,Monat!J62,Monat!J78,Monat!J94,Monat!J110+Monat!J126,Monat!J142,Monat!J158,Monat!J174,Monat!J190) -> 0 | ... S14: =SUM(Monat!S14,Monat!S30,Monat!S46,Monat!S62,Monat!S78,Monat!S94,Monat!S110+Monat!S126,Monat!S142,Monat!S158,Monat!S174,Monat!S190) -> 0
B15: Summe | C15: =SUM(Monat!C16,Monat!C32,Monat!C48,Monat!C64,Monat!C80,Monat!C96,Monat!C112+Monat!C128,Monat!C144,Monat!C160,Monat!C176,Monat!C192) -> 65 | D15: =SUM(Monat!D16,Monat!D32,Monat!D48,Monat!D64,Monat!D80,Monat!D96,Monat!D112+Monat!D128,Monat!D144,Monat!D160,Monat!D176,Monat!D192) -> 33 | E15: =SUM(Monat!E16,Monat!E32,Monat!E48,Monat!E64,Monat!E80,Monat!E96,Monat!E112+Monat!E128,Monat!E144,Monat!E160,Monat!E176,Monat!E192) -> 112 | F15: =SUM(Monat!F16,Monat!F32,Monat!F48,Monat!F64,Monat!F80,Monat!F96,Monat!F112+Monat!F128,Monat!F144,Monat!F160,Monat!F176,Monat!F192) -> 256 | G15: =SUM(Monat!G16,Monat!G32,Monat!G48,Monat!G64,Monat!G80,Monat!G96,Monat!G112+Monat!G128,Monat!G144,Monat!G160,Monat!G176,Monat!G192) -> 44 | H15: =SUM(Monat!H16,Monat!H32,Monat!H48,Monat!H64,Monat!H80,Monat!H96,Monat!H112+Monat!H128,Monat!H144,Monat!H160,Monat!H176,Monat!H192) -> 5 | I15: =SUM(Monat!I16,Monat!I32,Monat!I48,Monat!I64,Monat!I80,Monat!I96,Monat!I112+Monat!I128,Monat!I144,Monat!I160,Monat!I176,Monat!I192) -> 9 | J15: =SUM(Monat!J16,Monat!J32,Monat!J48,Monat!J64,Monat!J80,Monat!J96,Monat!J112+Monat!J128,Monat!J144,Monat!J160,Monat!J176,Monat!J192) -> 34 | ... S15: =SUM(Monat!S16,Monat!S32,Monat!S48,Monat!S64,Monat!S80,Monat!S96,Monat!S112+Monat!S128,Monat!S144,Monat!S160,Monat!S176,Monat!S192) -> 52

Sheet Monat
B2: Januar | D2: Arbeitstage | F2: 21 | I2: Samstage | K2: 4 | Y2: Mitarbeiter | Z2: IRTAZ | AA2: Std. ZEM | AB2: Schichten | AC2: Zeit | AD2: Urlaub in Std.
C3: =Jahr!C3 -> FI | D3: =Jahr!D3 -> FII | E3: =Jahr!E3 -> SI | F3: =Jahr!F3 -> NI | G3: =Jahr!G3 -> DI | H3: =Jahr!H3 -> DII | I3: =Jahr!I3 -> SD | J3: =Jahr!J3 -> GT | ... S3: =Jahr!S3 -> NST | T3: Soll AZ | U3: Ist AZ | V3: Differenz | W3: Gesamt | Y3: =B4 -> Breig | Z3: 8 | AA3: 0 | AB3: FI | AC3: 7.25 | AD3: =SUM(Z3*30) -> 240
B4: =Dienstplan!B8 -> Breig | C4: =SUMPRODUCT((ISNUMBER(SEARCH($Y3,Dienstplan!$B$8:$B$19))*(ISNUMBER(SEARCH($AB$3,Dienstplan!$C$8:$AG$19)))))-D4 -> 0 | D4: =SUMPRODUCT((ISNUMBER(SEARCH($Y3,Dienstplan!$B$8:$B$19))*(ISNUMBER(SEARCH($AB$4,Dienstplan!$C$8:$AG$19))))) -> 6 | E4: =SUMPRODUCT((ISNUMBER(SEARCH($Y3,Dienstplan!$B$8:$B$19))*(ISNUMBER(SEARCH($AB$5,Dienstplan!$C$8:$AG$19))))) -> 5 | F4: =SUMPRODUCT((ISNUMBER(SEARCH($Y3,Dienstplan!$B$8:$B$19))*(ISNUMBER(SEARCH($AB6,Dienstplan!$C$8:$AG$19)))))-1 -> 1 | G4: =SUMPRODUCT((ISNUMBER(SEARCH($Y3,Dienstplan!$B$8:$B$19))*(ISNUMBER(SEARCH(AB$7,Dienstplan!$C$8:$AG$19)))))-H4 -> 2 | H4: =SUMPRODUCT((ISNUMBER(SEARCH($Y3,Dienstplan!$B$8:$B$19))*(ISNUMBER(SEARCH(AB$8,Dienstplan!$C$8:$AG$19))))) -> 0 | I4: =SUMPRODUCT((ISNUMBER(SEARCH($Y3,Dienstplan!$B$8:$B$19))*(ISNUMBER(SEARCH($AB$9,Dienstplan!$C$8:$AG$19))))) -> 0 | J4: =SUMPRODUCT((ISNUMBER(SEARCH($Y3,Dienstplan!$B$8:$B$19))*(ISNUMBER(SEARCH($AB$10,Dienstplan!$C$8:$AG$19))))) -> 1 | K4: =SUMPRODUCT((ISNUMBER(SEARCH($Y3,Dienstplan!$B$8:$B$19))*(ISNUMBER(SEARCH($AB$11,Dienstplan!$C$8:$AG$19)))))-$Q4 -> 4 | L4: =SUMPRODUCT((ISNUMBER(SEARCH($Y3,Dienstplan!$B$8:$B$19))*(ISNUMBER(SEARCH($AB$12,Dienstplan!$C$8:$AG$19))))) -> 0 | M4: =SUMPRODUCT((ISNUMBER(SEARCH($Y3,Dienstplan!$B$8:$B$19))*(ISNUMBER(SEARCH($AB$13,Dienstplan!$C$8:$AG$19))))) -> 0 | N4: =SUMPRODUCT((ISNUMBER(SEARCH($Y3,Dienstplan!$B$8:$B$19))*(ISNUMBER(SEARCH($AB$14,Dienstplan!$C$8:$AG$19))))) -> 0 | O4: =SUMPRODUCT((ISNUMBER(SEARCH($Y3,Dienstplan!$B$8:$B$19))*(ISNUMBER(SEARCH($AB$15,Dienstplan!$C$8:$AG$19))))) -> 0 | P4: =SUMPRODUCT((ISNUMBER(SEARCH($Y3,Dienstplan!$B$8:$B$19))*(ISNUMBER(SEARCH($AB$16,Dienstplan!$C$8:$AG$19))))) -> 2 | Q4: =SUMPRODUCT((ISNUMBER(SEARCH($Y3,Dienstplan!$B$8:$B$19))*(ISNUMBER(SEARCH($AB$17,Dienstplan!$C$8:$AG$19))))) -> 0 | R4: =SUMPRODUCT((ISNUMBER(SEARCH($Y3,Dienstplan!$B$8:$B$19))*(ISNUMBER(SEARCH($AB$18,Dienstplan!$C$8:$AG$19))))) -> 0 | S4: =SUMPRODUCT((ISNUMBER(SEARCH($Y3,Dienstplan!$B$8:$B$19))*(ISNUMBER(SEARCH($AB$19,Dienstplan!$C$8:$AG$19))))) -> 0 | T4: =SUM($F$2*$Z3) -> 168 | U4: =SUM($C4*Frueh_1+$D4*Spaet_1+$E4*Nacht_1+$F4*Normal_1+$I4*Sonderd_1-$J4*Velten+$K4*Velten+$L4*EH_Kurs+$M4*Koor_taet+$N4*Sekre_1+$O4*Velten+$R4*Velten+$P4*Velten+$Q4*Velten+G4*Unt_I+H4*Unt_II) -> 146 | V4: =SUM($U4-$T4) -> -22 | W4: =V4+AA3 -> -22 | Y4: =B5 -> Siebert | Z4: 7 | AA4: 0 | AB4: FII | AC4: 7.5 | AD4: =SUM(Z4*30) -> 210
B5: =Dienstplan!B9 -> Siebert | C5: =SUMPRODUCT((ISNUMBER(SEARCH($Y4,Dienstplan!$B$8:$B$19))*(ISNUMBER(SEARCH($AB$3,Dienstplan!$C$8:$AG$19)))))-D5 -> 6 | D5: =SUMPRODUCT((ISNUMBER(SEARCH($Y4,Dienstplan!$B$8:$B$19))*(ISNUMBER(SEARCH($AB$4,Dienstplan!$C$8:$AG$19))))) -> 3 | E5: =SUMPRODUCT((ISNUMBER(SEARCH($Y4,Dienstplan!$B$8:$B$19))*(ISNUMBER(SEARCH($AB$5,Dienstplan!$C$8:$AG$19))))) -> 5 | F5: =SUMPRODUCT((ISNUMBER(SEARCH($Y4,Dienstplan!$B$8:$B$19))*(ISNUMBER(SEARCH($AB$6,Dienstplan!$C$8:$AG$19))))) -> 5 | G5: =SUMPRODUCT((ISNUMBER(SEARCH($Y4,Dienstplan!$B$8:$B$19))*(ISNUMBER(SEARCH(AB$7,Dienstplan!$C$8:$AG$19)))))-H5 -> 0 | H5: =SUMPRODUCT((ISNUMBER(SEARCH($Y4,Dienstplan!$B$8:$B$19))*(ISNUMBER(SEARCH(AB$8,Dienstplan!$C$8:$AG$19))))) -> 0 | I5: =SUMPRODUCT((ISNUMBER(SEARCH($Y4,Dienstplan!$B$8:$B$19))*(ISNUMBER(SEARCH($AB$9,Dienstplan!$C$8:$AG$19))))) -> 0 | J5: =SUMPRODUCT((ISNUMBER(SEARCH($Y4,Dienstplan!$B$8:$B$19))*(ISNUMBER(SEARCH($AB$10,Dienstplan!$C$8:$AG$19))))) -> 0 | K5: =SUMPRODUCT((ISNUMBER(SEARCH($Y4,Dienstplan!$B$8:$B$19))*(ISNUMBER(SEARCH($AB$11,Dienstplan!$C$8:$AG$19)))))-$Q5 -> 1 | L5: =SUMPRODUCT((ISNUMBER(SEARCH($Y4,Dienstplan!$B$8:$B$19))*(ISNUMBER(SEARCH($AB$12,Dienstplan!$C$8:$AG$19))))) -> 0 | M5: =SUMPRODUCT((ISNUMBER(SEARCH($Y4,Dienstplan!$B$8:$B$19))*(ISNUMBER(SEARCH($AB$13,Dienstplan!$C$8:$AG$19))))) -> 0 | N5: =SUMPRODUCT((ISNUMBER(SEARCH($Y4,Dienstplan!$B$8:$B$19))*(ISNUMBER(SEARCH($AB$14,Dienstplan!$C$8:$AG$19))))) -> 0 | O5: =SUMPRODUCT((ISNUMBER(SEARCH($Y4,Dienstplan!$B$8:$B$19))*(ISNUMBER(SEARCH($AB$15,Dienstplan!$C$8:$AG$19))))) -> 0 | P5: =SUMPRODUCT((ISNUMBER(SEARCH($Y4,Dienstplan!$B$8:$B$19))*(ISNUMBER(SEARCH($AB$16,Dienstplan!$C$8:$AG$19))))) -> 1 | Q5: =SUMPRODUCT((ISNUMBER(SEARCH($Y4,Dienstplan!$B$8:$B$19))*(ISNUMBER(SEARCH($AB$17,Dienstplan!$C$8:$AG$19))))) -> 0 | R5: =SUMPRODUCT((ISNUMBER(SEARCH($Y4,Dienstplan!$B$8:$B$19))*(ISNUMBER(SEARCH($AB$18,Dienstplan!$C$8:$AG$19))))) -> 0 | S5: =SUMPRODUCT((ISNUMBER(SEARCH($Y4,Dienstplan!$B$8:$B$19))*(ISNUMBER(SEARCH($AB$19,Dienstplan!$C$8:$AG$19))))) -> 2 | T5: =SUM($F$2*$Z4) -> 147 | U5: =SUM($C5*Frueh_1+$D5*Spaet_1+$E5*Nacht_1+$F5*Normal_1+$I5*Sonderd_1-$J5*Brue_H+$K5*Brue_H+$L5*EH_Kurs+$M5*Koor_taet+$N5*Sekre_1+$O5*Brue_H+$R5*Brue_H+$P5*Brue_H+$Q5*Brue_H+G5*Unt_I+H5*Unt_II) -> 155 | V5: =SUM($U5-$T5) -> 8 | W5: =V5+AA4 -> 8 | Y5: =B6 -> Jochim | Z5: 7 | AA5: 0 | AB5: SI | AC5: 7.5 | AD5: =SUM(Z5*30) -> 210
B6: =Dienstplan!B10 -> Jochim | C6: =SUMPRODUCT((ISNUMBER(SEARCH($Y5,Dienstplan!$B$8:$B$19))*(ISNUMBER(SEARCH($AB$3,Dienstplan!$C$8:$AG$19)))))-D6 -> 0 | D6: =SUMPRODUCT((ISNUMBER(SEARCH($Y5,Dienstplan!$B$8:$B$19))*(ISNUMBER(SEARCH($AB$4,Dienstplan!$C$8:$AG$19))))) -> 0 | E6: =SUMPRODUCT((ISNUMBER(SEARCH($Y5,Dienstplan!$B$8:$B$19))*(ISNUMBER(SEARCH($AB$5,Dienstplan!$C$8:$AG$19))))) -> 0 | F6: =SUMPRODUCT((ISNUMBER(SEARCH($Y5,Dienstplan!$B$8:$B$19))*(ISNUMBER(SEARCH($AB$6,Dienstplan!$C$8:$AG$19))))) -> 0 | G6: =SUMPRODUCT((ISNUMBER(SEARCH($Y5,Dienstplan!$B$8:$B$19))*(ISNUMBER(SEARCH(AB$7,Dienstplan!$C$8:$AG$19)))))-H6 -> 0 | H6: =SUMPRODUCT((ISNUMBER(SEARCH($Y5,Dienstplan!$B$8:$B$19))*(ISNUMBER(SEARCH(AB$8,Dienstplan!$C$8:$AG$19))))) -> 0 | I6: =SUMPRODUCT((ISNUMBER(SEARCH($Y5,Dienstplan!$B$8:$B$19))*(ISNUMBER(SEARCH($AB$9,Dienstplan!$C$8:$AG$19))))) -> 0 | J6: =SUMPRODUCT((ISNUMBER(SEARCH($Y5,Dienstplan!$B$8:$B$19))*(ISNUMBER(SEARCH($AB$10,Dienstplan!$C$8:$AG$19))))) -> 0 | K6: =SUMPRODUCT((ISNUMBER(SEARCH($Y5,Dienstplan!$B$8:$B$19))*(ISNUMBER(SEARCH($AB$11,Dienstplan!$C$8:$AG$19)))))-$Q6 -> 0 | L6: =SUMPRODUCT((ISNUMBER(SEARCH($Y5,Dienstplan!$B$8:$B$19))*(ISNUMBER(SEARCH($AB$12,Dienstplan!$C$8:$AG$19))))) -> 0 | M6: =SUMPRODUCT((ISNUMBER(SEARCH($Y5,Dienstplan!$B$8:$B$19))*(ISNUMBER(SEARCH($AB$13,Dienstplan!$C$8:$AG$19))))) -> 0 | N6: =SUMPRODUCT((ISNUMBER(SEARCH($Y5,Dienstplan!$B$8:$B$19))*(ISNUMBER(SEARCH($AB$14,Dienstplan!$C$8:$AG$19))))) -> 0 | O6: =SUMPRODUCT((ISNUMBER(SEARCH($Y5,Dienstplan!$B$8:$B$19))*(ISNUMBER(SEARCH($AB$15,Dienstplan!$C$8:$AG$19))))) -> 0 | P6: =SUMPRODUCT((ISNUMBER(SEARCH($Y5,Dienstplan!$B$8:$B$19))*(ISNUMBER(SEARCH($AB$16,Dienstplan!$C$8:$AG$19))))) -> 0 | Q6: =SUMPRODUCT((ISNUMBER(SEARCH($Y5,Dienstplan!$B$8:$B$19))*(ISNUMBER(SEARCH($AB$17,Dienstplan!$C$8:$AG$19))))) -> 0 | R6: =SUMPRODUCT((ISNUMBER(SEARCH($Y5,Dienstplan!$B$8:$B$19))*(ISNUMBER(SEARCH($AB$18,Dienstplan!$C$8:$AG$19))))) -> 0 | S6: =SUMPRODUCT((ISNUMBER(SEARCH($Y5,Dienstplan!$B$8:$B$19))*(ISNUMBER(SEARCH($AB$19,Dienstplan!$C$8:$AG$19))))) -> 0 | T6: =SUM($F$2*$Z5) -> 147 | U6: =SUM($C6*Frueh_1+$D6*Spaet_1+$E6*Nacht_1+$F6*Normal_1+$I6*Sonderd_1-$J6*Rath_M+$K6*Rath_M+$L6*EH_Kurs+$M6*Koor_taet+$N6*Sekre_1+$O6*Rath_M+$R6*Rath_M+$P6*Rath_M+$Q6*Rath_M+G6*Unt_I+H6*Unt_II) -> 0 | V6: =SUM($U6-$T6) -> -147 | W6: =V6+AA5 -> -147 | Y6: =B7 -> Wunsch | Z6: 8 | AA6: 0 | AB6: NI | AC6: 7.5 | AD6: =SUM(Z6*30) -> 240
B7: =Dienstplan!B11 -> Wunsch | C7: =SUMPRODUCT((ISNUMBER(SEARCH($Y6,Dienstplan!$B$8:$B$19))*(ISNUMBER(SEARCH($AB$3,Dienstplan!$C$8:$AG$19)))))-D7 -> 5 | D7: =SUMPRODUCT((ISNUMBER(SEARCH($Y6,Dienstplan!$B$8:$B$19))*(ISNUMBER(SEARCH($AB$4,Dienstplan!$C$8:$AG$19))))) -> 0 | E7: =SUMPRODUCT((ISNUMBER(SEARCH($Y6,Dienstplan!$B$8:$B$19))*(ISNUMBER(SEARCH($AB$5,Dienstplan!$C$8:$AG$19))))) -> 5 | F7: =SUMPRODUCT((ISNUMBER(SEARCH($Y6,Dienstplan!$B$8:$B$19))*(ISNUMBER(SEARCH($AB$6,Dienstplan!$C$8:$AG$19))))) -> 5 | G7: =SUMPRODUCT((ISNUMBER(SEARCH($Y6,Dienstplan!$B$8:$B$19))*(ISNUMBER(SEARCH(AB$7,Dienstplan!$C$8:$AG$19)))))-H7 -> 3 | H7: =SUMPRODUCT((ISNUMBER(SEARCH($Y6,Dienstplan!$B$8:$B$19))*(ISNUMBER(SEARCH(AB$8,Dienstplan!$C$8:$AG$19))))) -> 0 | I7: =SUMPRODUCT((ISNUMBER(SEARCH($Y6,Dienstplan!$B$8:$B$19))*(ISNUMBER(SEARCH($AB$9,Dienstplan!$C$8:$AG$19))))) -> 2 | J7: =SUMPRODUCT((ISNUMBER(SEARCH($Y6,Dienstplan!$B$8:$B$19))*(ISNUMBER(SEARCH($AB$10,Dienstplan!$C$8:$AG$19))))) -> 0 | K7: =SUMPRODUCT((ISNUMBER(SEARCH($Y6,Dienstplan!$B$8:$B$19))*(ISNUMBER(SEARCH($AB$11,Dienstplan!$C$8:$AG$19)))))-$Q7 -> 0 | L7: =SUMPRODUCT((ISNUMBER(SEARCH($Y6,Dienstplan!$B$8:$B$19))*(ISNUMBER(SEARCH($AB$12,Dienstplan!$C$8:$AG$19))))) -> 0 | M7: =SUMPRODUCT((ISNUMBER(SEARCH($Y6,Dienstplan!$B$8:$B$19))*(ISNUMBER(SEARCH($AB$13,Dienstplan!$C$8:$AG$19))))) -> 0 | N7: =SUMPRODUCT((ISNUMBER(SEARCH($Y6,Dienstplan!$B$8:$B$19))*(ISNUMBER(SEARCH($AB$14,Dienstplan!$C$8:$AG$19))))) -> 0 | O7: =SUMPRODUCT((ISNUMBER(SEARCH($Y6,Dienstplan!$B$8:$B$19))*(ISNUMBER(SEARCH($AB$15,Dienstplan!$C$8:$AG$19))))) -> 0 | P7: =SUMPRODUCT((ISNUMBER(SEARCH($Y6,Dienstplan!$B$8:$B$19))*(ISNUMBER(SEARCH($AB$16,Dienstplan!$C$8:$AG$19))))) -> 0 | Q7: =SUMPRODUCT((ISNUMBER(SEARCH($Y6,Dienstplan!$B$8:$B$19))*(ISNUMBER(SEARCH($AB$17,Dienstplan!$C$8:$AG$19))))) -> 0 | R7: =SUMPRODUCT((ISNUMBER(SEARCH($Y6,Dienstplan!$B$8:$B$19))*(ISNUMBER(SEARCH($AB$18,Dienstplan!$C$8:$AG$19))))) -> 0 | S7: =SUMPRODUCT((ISNUMBER(SEARCH($Y6,Dienstplan!$B$8:$B$19))*(ISNUMBER(SEARCH($AB$19,Dienstplan!$C$8:$AG$19))))) -> 1 | T7: =SUM($F$2*$Z6) -> 168 | U7: =SUM($C7*Frueh_1+$D7*Spaet_1+$E7*Nacht_1+$F7*Normal_1+$I7*Sonderd_1-$J7*Scho_K+$K7*Scho_K+$L7*EH_Kurs+$M7*Koor_taet+$N7*Sekre_1+$O7*Scho_K+$R7*Scho_K+$P7*Scho_K+$Q7*Scho_K+G7*Unt_I+H7*Unt_II) -> 149.25 | V7: =SUM($U7-$T7) -> -18.75 | W7: =V7+AA6 -> -18.75 | Y7: =B8 -> Göpfrich | Z7: 7 | AA7: 0 | AB7: DI | AC7: 8 | AD7: =SUM(Z7*30) -> 210
B8: =Dienstplan!B12 -> Göpfrich | C8: =SUMPRODUCT((ISNUMBER(SEARCH($Y7,Dienstplan!$B$8:$B$19))*(ISNUMBER(SEARCH($AB$3,Dienstplan!$C$8:$AG$19)))))-D8 -> 0 | D8: =SUMPRODUCT((ISNUMBER(SEARCH($Y7,Dienstplan!$B$8:$B$19))*(ISNUMBER(SEARCH($AB$4,Dienstplan!$C$8:$AG$19))))) -> 0 | E8: =SUMPRODUCT((ISNUMBER(SEARCH($Y7,Dienstplan!$B$8:$B$19))*(ISNUMBER(SEARCH($AB$5,Dienstplan!$C$8:$AG$19))))) -> 3 | F8: =SUMPRODUCT((ISNUMBER(SEARCH($Y7,Dienstplan!$B$8:$B$19))*(ISNUMBER(SEARCH($AB$6,Dienstplan!$C$8:$AG$19))))) -> 6 | G8: =SUMPRODUCT((ISNUMBER(SEARCH($Y7,Dienstplan!$B$8:$B$19))*(ISNUMBER(SEARCH(AB$7,Dienstplan!$C$8:$AG$19)))))-H8 -> 3 | H8: =SUMPRODUCT((ISNUMBER(SEARCH($Y7,Dienstplan!$B$8:$B$19))*(ISNUMBER(SEARCH(AB$8,Dienstplan!$C$8:$AG$19))))) -> 0 | I8: =SUMPRODUCT((ISNUMBER(SEARCH($Y7,Dienstplan!$B$8:$B$19))*(ISNUMBER(SEARCH($AB$9,Dienstplan!$C$8:$AG$19))))) -> 0 | J8: =SUMPRODUCT((ISNUMBER(SEARCH($Y7,Dienstplan!$B$8:$B$19))*(ISNUMBER(SEARCH($AB$10,Dienstplan!$C$8:$AG$19))))) -> 0 | K8: =SUMPRODUCT((ISNUMBER(SEARCH($Y7,Dienstplan!$B$8:$B$19))*(ISNUMBER(SEARCH($AB$11,Dienstplan!$C$8:$AG$19)))))-$Q8 -> 9 | L8: =SUMPRODUCT((ISNUMBER(SEARCH($Y7,Dienstplan!$B$8:$B$19))*(ISNUMBER(SEARCH($AB$12,Dienstplan!$C$8:$AG$19))))) -> 0 | M8: =SUMPRODUCT((ISNUMBER(SEARCH($Y7,Dienstplan!$B$8:$B$19))*(ISNUMBER(SEARCH($AB$13,Dienstplan!$C$8:$AG$19))))) -> 0 | N8: =SUMPRODUCT((ISNUMBER(SEARCH($Y7,Dienstplan!$B$8:$B$19))*(ISNUMBER(SEARCH($AB$14,Dienstplan!$C$8:$AG$19))))) -> 0 | O8: =SUMPRODUCT((ISNUMBER(SEARCH($Y7,Dienstplan!$B$8:$B$19))*(ISNUMBER(SEARCH($AB$15,Dienstplan!$C$8:$AG$19))))) -> 0 | P8: =SUMPRODUCT((ISNUMBER(SEARCH($Y7,Dienstplan!$B$8:$B$19))*(ISNUMBER(SEARCH($AB$16,Dienstplan!$C$8:$AG$19))))) -> 2 | Q8: =SUMPRODUCT((ISNUMBER(SEARCH($Y7,Dienstplan!$B$8:$B$19))*(ISNUMBER(SEARCH($AB$17,Dienstplan!$C$8:$AG$19))))) -> 0 | R8: =SUMPRODUCT((ISNUMBER(SEARCH($Y7,Dienstplan!$B$8:$B$19))*(ISNUMBER(SEARCH($AB$18,Dienstplan!$C$8:$AG$19))))) -> 0 | S8: =SUMPRODUCT((ISNUMBER(SEARCH($Y7,Dienstplan!$B$8:$B$19))*(ISNUMBER(SEARCH($AB$19,Dienstplan!$C$8:$AG$19))))) -> 0 | T8: =SUM($F$2*$Z7) -> 147 | U8: =SUM($C8*Frueh_1+$D8*Spaet_1+$E8*Nacht_1+$F8*Normal_1+$I8*Sonderd_1-$J8*Krie_B+$K8*Krie_B+$L8*EH_Kurs+$M8*Koor_taet+$N8*Sekre_1+$O8*Krie_B+$R8*Krie_B+$P8*Krie_B+$Q8*Krie_B+G8*Unt_I+H8*Unt_II) -> 168.5 | V8: =SUM($U8-$T8) -> 21.5 | W8: =V8+AA7 -> 21.5 | Y8: =B9 -> Zeller | Z8: 8 | AA8: 0 | AB8: DII | AC8: 8 | AD8: =SUM(Z8*30) -> 240
B9: =Dienstplan!B13 -> Zeller | C9: =SUMPRODUCT((ISNUMBER(SEARCH($Y8,Dienstplan!$B$8:$B$19))*(ISNUMBER(SEARCH($AB$3,Dienstplan!$C$8:$AG$19)))))-D9 -> 9 | D9: =SUMPRODUCT((ISNUMBER(SEARCH($Y8,Dienstplan!$B$8:$B$19))*(ISNUMBER(SEARCH($AB$4,Dienstplan!$C$8:$AG$19))))) -> 4 | E9: =SUMPRODUCT((ISNUMBER(SEARCH($Y8,Dienstplan!$B$8:$B$19))*(ISNUMBER(SEARCH($AB$5,Dienstplan!$C$8:$AG$19))))) -> 0 | F9: =SUMPRODUCT((ISNUMBER(SEARCH($Y8,Dienstplan!$B$8:$B$19))*(ISNUMBER(SEARCH($AB$6,Dienstplan!$C$8:$AG$19))))) -> 0 | G9: =SUMPRODUCT((ISNUMBER(SEARCH($Y8,Dienstplan!$B$8:$B$19))*(ISNUMBER(SEARCH(AB$7,Dienstplan!$C$8:$AG$19)))))-H9 -> 3 | H9: =SUMPRODUCT((ISNUMBER(SEARCH($Y8,Dienstplan!$B$8:$B$19))*(ISNUMBER(SEARCH(AB$8,Dienstplan!$C$8:$AG$19))))) -> 0 | I9: =SUMPRODUCT((ISNUMBER(SEARCH($Y8,Dienstplan!$B$8:$B$19))*(ISNUMBER(SEARCH($AB$9,Dienstplan!$C$8:$AG$19))))) -> 0 | J9: =SUMPRODUCT((ISNUMBER(SEARCH($Y8,Dienstplan!$B$8:$B$19))*(ISNUMBER(SEARCH($AB$10,Dienstplan!$C$8:$AG$19))))) -> 1 | K9: =SUMPRODUCT((ISNUMBER(SEARCH($Y8,Dienstplan!$B$8:$B$19))*(ISNUMBER(SEARCH($AB$11,Dienstplan!$C$8:$AG$19)))))-$Q9 -> 3 | L9: =SUMPRODUCT((ISNUMBER(SEARCH($Y8,Dienstplan!$B$8:$B$19))*(ISNUMBER(SEARCH($AB$12,Dienstplan!$C$8:$AG$19))))) -> 0 | M9: =SUMPRODUCT((ISNUMBER(SEARCH($Y8,Dienstplan!$B$8:$B$19))*(ISNUMBER(SEARCH($AB$13,Dienstplan!$C$8:$AG$19))))) -> 0 | N9: =SUMPRODUCT((ISNUMBER(SEARCH($Y8,Dienstplan!$B$8:$B$19))*(ISNUMBER(SEARCH($AB$14,Dienstplan!$C$8:$AG$19))))) -> 0 | O9: =SUMPRODUCT((ISNUMBER(SEARCH($Y8,Dienstplan!$B$8:$B$19))*(ISNUMBER(SEARCH($AB$15,Dienstplan!$C$8:$AG$19))))) -> 0 | P9: =SUMPRODUCT((ISNUMBER(SEARCH($Y8,Dienstplan!$B$8:$B$19))*(ISNUMBER(SEARCH($AB$16,Dienstplan!$C$8:$AG$19))))) -> 1 | Q9: =SUMPRODUCT((ISNUMBER(SEARCH($Y8,Dienstplan!$B$8:$B$19))*(ISNUMBER(SEARCH($AB$17,Dienstplan!$C$8:$AG$19))))) -> 0 | R9: =SUMPRODUCT((ISNUMBER(SEARCH($Y8,Dienstplan!$B$8:$B$19))*(ISNUMBER(SEARCH($AB$18,Dienstplan!$C$8:$AG$19))))) -> 0 | S9: =SUMPRODUCT((ISNUMBER(SEARCH($Y8,Dienstplan!$B$8:$B$19))*(ISNUMBER(SEARCH($AB$19,Dienstplan!$C$8:$AG$19))))) -> 1 | T9: =SUM($F$2*$Z8) -> 168 | U9: =SUM($C9*Frueh_1+$D9*Spaet_1+$E9*Nacht_1+$F9*Normal_1+$I9*Sonderd_1-$J9*Wuert_A+$K9*Wuert_A+$L9*EH_Kurs+$M9*Koor_taet+$N9*Sekre_1+$O9*Wuert_A+$R9*Wuert_A+$P9*Wuert_A+$Q9*Wuert_A+G9*Unt_I+H9*Unt_II) -> 143.25 | V9: =SUM($U9-$T9) -> -24.75 | W9: =V9+AA8 -> -24.75 | Y9: =B10 -> Behrendt | Z9: 7 | AA9: 0 | AB9: SD | AC9: 7 | AD9: =SUM(Z10*30) -> 96
B10: =Dienstplan!B14 -> Behrendt | C10: {=SUMPRODUCT((ISNUMBER(SEARCH($Y9,Dienstplan!$B$8:$B$19))*(ISNUMBER(SEARCH($AB$3,Dienstplan!$C$8:$AG$19)))))-D10} -> 0 | D10: {=SUMPRODUCT((ISNUMBER(SEARCH($Y9,Dienstplan!$B$8:$B$19))*(ISNUMBER(SEARCH($AB$4,Dienstplan!$C$8:$AG$19)))))} -> 0 | E10: {=SUMPRODUCT((ISNUMBER(SEARCH($Y9,Dienstplan!$B$8:$B$19))*(ISNUMBER(SEARCH($AB$5,Dienstplan!$C$8:$AG$19)))))} -> 0 | F10: {=SUMPRODUCT((ISNUMBER(SEARCH($Y9,Dienstplan!$B$8:$B$19))*(ISNUMBER(SEARCH($AB$6,Dienstplan!$C$8:$AG$19)))))} -> 0 | G10: {=SUMPRODUCT((ISNUMBER(SEARCH($Y9,Dienstplan!$B$8:$B$19))*(ISNUMBER(SEARCH(AB$7,Dienstplan!$C$8:$AG$19)))))-H10} -> 0 | H10: {=SUMPRODUCT((ISNUMBER(SEARCH($Y9,Dienstplan!$B$8:$B$19))*(ISNUMBER(SEARCH(AB$8,Dienstplan!$C$8:$AG$19)))))} -> 0 | I10: {=SUMPRODUCT((ISNUMBER(SEARCH($Y9,Dienstplan!$B$8:$B$19))*(ISNUMBER(SEARCH($AB$9,Dienstplan!$C$8:$AG$19)))))} -> 0 | J10: {=SUMPRODUCT((ISNUMBER(SEARCH($Y9,Dienstplan!$B$8:$B$19))*(ISNUMBER(SEARCH($AB$10,Dienstplan!$C$8:$AG$19)))))} -> 0 | K10: {=SUMPRODUCT((ISNUMBER(SEARCH($Y9,Dienstplan!$B$8:$B$19))*(ISNUMBER(SEARCH($AB$11,Dienstplan!$C$8:$AG$19)))))-$Q10} -> 0 | L10: {=SUMPRODUCT((ISNUMBER(SEARCH($Y9,Dienstplan!$B$8:$B$19))*(ISNUMBER(SEARCH($AB$12,Dienstplan!$C$8:$AG$19)))))} -> 0 | M10: {=SUMPRODUCT((ISNUMBER(SEARCH($Y9,Dienstplan!$B$8:$B$19))*(ISNUMBER(SEARCH($AB$13,Dienstplan!$C$8:$AG$19)))))} -> 0 | N10: {=SUMPRODUCT((ISNUMBER(SEARCH($Y9,Dienstplan!$B$8:$B$19))*(ISNUMBER(SEARCH($AB$14,Dienstplan!$C$8:$AG$19)))))} -> 0 | O10: {=SUMPRODUCT((ISNUMBER(SEARCH($Y9,Dienstplan!$B$8:$B$19))*(ISNUMBER(SEARCH($AB$15,Dienstplan!$C$8:$AG$19)))))} -> 0 | P10: {=SUMPRODUCT((ISNUMBER(SEARCH($Y9,Dienstplan!$B$8:$B$19))*(ISNUMBER(SEARCH($AB$16,Dienstplan!$C$8:$AG$19)))))} -> 0 | Q10: {=SUMPRODUCT((ISNUMBER(SEARCH($Y9,Dienstplan!$B$8:$B$19))*(ISNUMBER(SEARCH($AB$17,Dienstplan!$C$8:$AG$19)))))} -> 0 | R10: {=SUMPRODUCT((ISNUMBER(SEARCH($Y9,Dienstplan!$B$8:$B$19))*(ISNUMBER(SEARCH($AB$18,Dienstplan!$C$8:$AG$19)))))} -> 0 | S10: {=SUMPRODUCT((ISNUMBER(SEARCH($Y9,Dienstplan!$B$8:$B$19))*(ISNUMBER(SEARCH($AB$19,Dienstplan!$C$8:$AG$19)))))} -> 0 | T10: =SUM($F$2*$Z10) -> 67.2 | U10: =SUM($C10*Frueh_1+$D10*Spaet_1+$E10*Nacht_1+$F10*Normal_1+$I10*Sonderd_1-$J10*Wuert_A+$K10*Wuert_A+$L10*EH_Kurs+$M10*Koor_taet+$N10*Sekre_1+$O10*Wuert_A+$R10*Wuert_A+$P10*Wuert_A+$Q10*Wuert_A+G10*Unt_I+H10*Unt_II) -> 0 | V10: =SUM($U10-$T10) -> -67.2 | W10: =V10+AA9 -> -67.2 | Y10: =B11 -> Krempl | Z10: 3.2 | AA10: 0 | AB10: GT | AC10: IRTAZ | AD10: =SUM(Z11*30) -> 240
B11: =Dienstplan!B15 -> Krempl | C11: =SUMPRODUCT((ISNUMBER(SEARCH($Y10,Dienstplan!$B$8:$B$19))*(ISNUMBER(SEARCH($AB$3,Dienstplan!$C$8:$AG$19)))))-D11 -> 0 | D11: =SUMPRODUCT((ISNUMBER(SEARCH($Y10,Dienstplan!$B$8:$B$19))*(ISNUMBER(SEARCH($AB$4,Dienstplan!$C$8:$AG$19))))) -> 0 | E11: =SUMPRODUCT((ISNUMBER(SEARCH($Y10,Dienstplan!$B$8:$B$19))*(ISNUMBER(SEARCH($AB$5,Dienstplan!$C$8:$AG$19))))) -> 0 | F11: =SUMPRODUCT((ISNUMBER(SEARCH($Y10,Dienstplan!$B$8:$B$19))*(ISNUMBER(SEARCH($AB$6,Dienstplan!$C$8:$AG$19))))) -> 0 | G11: =SUMPRODUCT((ISNUMBER(SEARCH($Y10,Dienstplan!$B$8:$B$19))*(ISNUMBER(SEARCH(AB$7,Dienstplan!$C$8:$AG$19)))))-H11 -> 5 | H11: =SUMPRODUCT((ISNUMBER(SEARCH($Y10,Dienstplan!$B$8:$B$19))*(ISNUMBER(SEARCH(AB$8,Dienstplan!$C$8:$AG$19))))) -> 0 | I11: =SUMPRODUCT((ISNUMBER(SEARCH($Y10,Dienstplan!$B$8:$B$19))*(ISNUMBER(SEARCH($AB$9,Dienstplan!$C$8:$AG$19))))) -> 0 | J11: =SUMPRODUCT((ISNUMBER(SEARCH($Y10,Dienstplan!$B$8:$B$19))*(ISNUMBER(SEARCH($AB$10,Dienstplan!$C$8:$AG$19))))) -> 10 | K11: =SUMPRODUCT((ISNUMBER(SEARCH($Y10,Dienstplan!$B$8:$B$19))*(ISNUMBER(SEARCH($AB$11,Dienstplan!$C$8:$AG$19)))))-$Q11 -> 5 | L11: =SUMPRODUCT((ISNUMBER(SEARCH($Y10,Dienstplan!$B$8:$B$19))*(ISNUMBER(SEARCH($AB$12,Dienstplan!$C$8:$AG$19))))) -> 0 | M11: =SUMPRODUCT((ISNUMBER(SEARCH($Y10,Dienstplan!$B$8:$B$19))*(ISNUMBER(SEARCH($AB$13,Dienstplan!$C$8:$AG$19))))) -> 0 | N11: =SUMPRODUCT((ISNUMBER(SEARCH($Y10,Dienstplan!$B$8:$B$19))*(ISNUMBER(SEARCH($AB$14,Dienstplan!$C$8:$AG$19))))) -> 0 | O11: =SUMPRODUCT((ISNUMBER(SEARCH($Y10,Dienstplan!$B$8:$B$19))*(ISNUMBER(SEARCH($AB$15,Dienstplan!$C$8:$AG$19))))) -> 0 | P11: =SUMPRODUCT((ISNUMBER(SEARCH($Y10,Dienstplan!$B$8:$B$19))*(ISNUMBER(SEARCH($AB$16,Dienstplan!$C$8:$AG$19))))) -> 2 | Q11: =SUMPRODUCT((ISNUMBER(SEARCH($Y10,Dienstplan!$B$8:$B$19))*(ISNUMBER(SEARCH($AB$17,Dienstplan!$C$8:$AG$19))))) -> 0 | R11: =SUMPRODUCT((ISNUMBER(SEARCH($Y10,Dienstplan!$B$8:$B$19))*(ISNUMBER(SEARCH($AB$18,Dienstplan!$C$8:$AG$19))))) -> 0 | S11: =SUMPRODUCT((ISNUMBER(SEARCH($Y10,Dienstplan!$B$8:$B$19))*(ISNUMBER(SEARCH($AB$19,Dienstplan!$C$8:$AG$19))))) -> 0 | T11: =SUM($F$2*$Z10) -> 67.2 | U11: =SUM($C11*Frueh_1+$D11*Spaet_1+$E11*Nacht_1+$F11*Normal_1+$I11*Sonderd_1-$J11*Krem_E+$K11*Krem_E+$L11*EH_Kurs+$M11*Koor_taet+$N11*Sekre_1+$O11*Krem_E+$R11*Krem_E+$P11*Krem_E+$Q11*Krem_E+G11*Unt_I+H11*Unt_II) -> 30.4 | V11: =SUM($U11-$T11) -> -36.8 | W11: =V11+AA9 -> -36.8 | Y11: =B12 -> Putschler | Z11: 8 | AA11: 0 | AB11: U | AC11: IRTAZ | AD11: =SUM(Z12*30) -> 210
